WARNING:tensorflow:From /data2/MECo/tensorflow_models/models-1.11/official/utils/logs/hooks.py:28: The name tf.train.SessionRunHook is deprecated. Please use tf.estimator.SessionRunHook instead.

WARNING:tensorflow:From /data2/MECo/tensorflow_models/models-1.11/official/utils/logs/metric_hook.py:24: The name tf.train.LoggingTensorHook is deprecated. Please use tf.estimator.LoggingTensorHook instead.

WARNING:tensorflow:From imagenet_main.py:349: The name tf.logging.set_verbosity is deprecated. Please use tf.compat.v1.logging.set_verbosity instead.

WARNING:tensorflow:From imagenet_main.py:349: The name tf.logging.INFO is deprecated. Please use tf.compat.v1.logging.INFO instead.

2020-05-18 07:34:35.497488: I tensorflow/core/platform/cpu_feature_guard.cc:142] Your CPU supports instructions that this TensorFlow binary was not compiled to use: AVX2 FMA
2020-05-18 07:34:35.532585: I tensorflow/stream_executor/platform/default/dso_loader.cc:42] Successfully opened dynamic library libcuda.so.1
2020-05-18 07:34:35.765557: I tensorflow/compiler/xla/service/service.cc:168] XLA service 0x55eb1a7877a0 executing computations on platform CUDA. Devices:
2020-05-18 07:34:35.765583: I tensorflow/compiler/xla/service/service.cc:175]   StreamExecutor device (0): GeForce GTX 1080 Ti, Compute Capability 6.1
2020-05-18 07:34:35.765588: I tensorflow/compiler/xla/service/service.cc:175]   StreamExecutor device (1): GeForce GTX 1080 Ti, Compute Capability 6.1
2020-05-18 07:34:35.801244: I tensorflow/core/platform/profile_utils/cpu_utils.cc:94] CPU Frequency: 2999735000 Hz
2020-05-18 07:34:35.802558: I tensorflow/compiler/xla/service/service.cc:168] XLA service 0x55eb1a9278c0 executing computations on platform Host. Devices:
2020-05-18 07:34:35.802580: I tensorflow/compiler/xla/service/service.cc:175]   StreamExecutor device (0): <undefined>, <undefined>
2020-05-18 07:34:35.805033: I tensorflow/core/common_runtime/gpu/gpu_device.cc:1640] Found device 0 with properties: 
name: GeForce GTX 1080 Ti major: 6 minor: 1 memoryClockRate(GHz): 1.6705
pciBusID: 0000:02:00.0
2020-05-18 07:34:35.805944: I tensorflow/core/common_runtime/gpu/gpu_device.cc:1640] Found device 1 with properties: 
name: GeForce GTX 1080 Ti major: 6 minor: 1 memoryClockRate(GHz): 1.6705
pciBusID: 0000:03:00.0
2020-05-18 07:34:35.806488: I tensorflow/stream_executor/platform/default/dso_loader.cc:42] Successfully opened dynamic library libcudart.so.10.0
2020-05-18 07:34:35.813397: I tensorflow/stream_executor/platform/default/dso_loader.cc:42] Successfully opened dynamic library libcublas.so.10.0
2020-05-18 07:34:35.829062: I tensorflow/stream_executor/platform/default/dso_loader.cc:42] Successfully opened dynamic library libcufft.so.10.0
2020-05-18 07:34:35.831904: I tensorflow/stream_executor/platform/default/dso_loader.cc:42] Successfully opened dynamic library libcurand.so.10.0
2020-05-18 07:34:35.838553: I tensorflow/stream_executor/platform/default/dso_loader.cc:42] Successfully opened dynamic library libcusolver.so.10.0
2020-05-18 07:34:35.845485: I tensorflow/stream_executor/platform/default/dso_loader.cc:42] Successfully opened dynamic library libcusparse.so.10.0
2020-05-18 07:34:35.865290: I tensorflow/stream_executor/platform/default/dso_loader.cc:42] Successfully opened dynamic library libcudnn.so.7
2020-05-18 07:34:35.867803: I tensorflow/core/common_runtime/gpu/gpu_device.cc:1763] Adding visible gpu devices: 0, 1
2020-05-18 07:34:35.867849: I tensorflow/stream_executor/platform/default/dso_loader.cc:42] Successfully opened dynamic library libcudart.so.10.0
2020-05-18 07:34:35.873342: I tensorflow/core/common_runtime/gpu/gpu_device.cc:1181] Device interconnect StreamExecutor with strength 1 edge matrix:
2020-05-18 07:34:35.873363: I tensorflow/core/common_runtime/gpu/gpu_device.cc:1187]      0 1 
2020-05-18 07:34:35.873369: I tensorflow/core/common_runtime/gpu/gpu_device.cc:1200] 0:   N Y 
2020-05-18 07:34:35.873373: I tensorflow/core/common_runtime/gpu/gpu_device.cc:1200] 1:   Y N 
2020-05-18 07:34:35.875218: I tensorflow/core/common_runtime/gpu/gpu_device.cc:1326] Created TensorFlow device (/device:GPU:0 with 10083 MB memory) -> physical GPU (device: 0, name: GeForce GTX 1080 Ti, pci bus id: 0000:02:00.0, compute capability: 6.1)
2020-05-18 07:34:35.876339: I tensorflow/core/common_runtime/gpu/gpu_device.cc:1326] Created TensorFlow device (/device:GPU:1 with 10479 MB memory) -> physical GPU (device: 1, name: GeForce GTX 1080 Ti, pci bus id: 0000:03:00.0, compute capability: 6.1)
WARNING:tensorflow:From /data2/MECo/tensorflow_models/models-1.11/official/resnet/resnet_run_loop.py:382: The name tf.ConfigProto is deprecated. Please use tf.compat.v1.ConfigProto instead.

W0518 07:34:35.879833 140469935716096 deprecation_wrapper.py:119] From /data2/MECo/tensorflow_models/models-1.11/official/resnet/resnet_run_loop.py:382: The name tf.ConfigProto is deprecated. Please use tf.compat.v1.ConfigProto instead.

WARNING:tensorflow:
The TensorFlow contrib module will not be included in TensorFlow 2.0.
For more information, please see:
  * https://github.com/tensorflow/community/blob/master/rfcs/20180907-contrib-sunset.md
  * https://github.com/tensorflow/addons
  * https://github.com/tensorflow/io (for I/O related ops)
If you depend on functionality not listed there, please file an issue.

W0518 07:34:36.484092 140469935716096 lazy_loader.py:50] 
The TensorFlow contrib module will not be included in TensorFlow 2.0.
For more information, please see:
  * https://github.com/tensorflow/community/blob/master/rfcs/20180907-contrib-sunset.md
  * https://github.com/tensorflow/addons
  * https://github.com/tensorflow/io (for I/O related ops)
If you depend on functionality not listed there, please file an issue.

INFO:tensorflow:Initializing RunConfig with distribution strategies.
I0518 07:34:36.484996 140469935716096 run_config.py:558] Initializing RunConfig with distribution strategies.
INFO:tensorflow:Not using Distribute Coordinator.
I0518 07:34:36.485134 140469935716096 estimator_training.py:167] Not using Distribute Coordinator.
INFO:tensorflow:Using config: {'_model_dir': './resnet_21', '_tf_random_seed': None, '_save_summary_steps': 100, '_save_checkpoints_steps': None, '_save_checkpoints_secs': 600, '_session_config': allow_soft_placement: true
, '_keep_checkpoint_max': 5, '_keep_checkpoint_every_n_hours': 10000, '_log_step_count_steps': 100, '_train_distribute': <tensorflow.python.distribute.one_device_strategy.OneDeviceStrategyV1 object at 0x7fc0942070b8>, '_device_fn': None, '_protocol': None, '_eval_distribute': None, '_experimental_distribute': None, '_experimental_max_worker_delay_secs': None, '_service': None, '_cluster_spec': <tensorflow.python.training.server_lib.ClusterSpec object at 0x7fc0942072b0>, '_task_type': 'worker', '_task_id': 0, '_global_id_in_cluster': 0, '_master': '', '_evaluation_master': '', '_is_chief': True, '_num_ps_replicas': 0, '_num_worker_replicas': 1, '_distribute_coordinator_mode': None}
I0518 07:34:36.486073 140469935716096 estimator.py:209] Using config: {'_model_dir': './resnet_21', '_tf_random_seed': None, '_save_summary_steps': 100, '_save_checkpoints_steps': None, '_save_checkpoints_secs': 600, '_session_config': allow_soft_placement: true
, '_keep_checkpoint_max': 5, '_keep_checkpoint_every_n_hours': 10000, '_log_step_count_steps': 100, '_train_distribute': <tensorflow.python.distribute.one_device_strategy.OneDeviceStrategyV1 object at 0x7fc0942070b8>, '_device_fn': None, '_protocol': None, '_eval_distribute': None, '_experimental_distribute': None, '_experimental_max_worker_delay_secs': None, '_service': None, '_cluster_spec': <tensorflow.python.training.server_lib.ClusterSpec object at 0x7fc0942072b0>, '_task_type': 'worker', '_task_id': 0, '_global_id_in_cluster': 0, '_master': '', '_evaluation_master': '', '_is_chief': True, '_num_ps_replicas': 0, '_num_worker_replicas': 1, '_distribute_coordinator_mode': None}
WARNING:tensorflow:From /data2/MECo/tensorflow_models/models-1.11/official/utils/logs/logger.py:149: The name tf.logging.info is deprecated. Please use tf.compat.v1.logging.info instead.

W0518 07:34:36.486599 140469935716096 deprecation_wrapper.py:119] From /data2/MECo/tensorflow_models/models-1.11/official/utils/logs/logger.py:149: The name tf.logging.info is deprecated. Please use tf.compat.v1.logging.info instead.

WARNING:tensorflow:From /data2/MECo/tensorflow_models/models-1.11/official/utils/logs/logger.py:342: The name tf.VERSION is deprecated. Please use tf.version.VERSION instead.

W0518 07:34:36.486726 140469935716096 deprecation_wrapper.py:119] From /data2/MECo/tensorflow_models/models-1.11/official/utils/logs/logger.py:342: The name tf.VERSION is deprecated. Please use tf.version.VERSION instead.

WARNING:tensorflow:From /data2/MECo/tensorflow_models/models-1.11/official/utils/logs/logger.py:342: The name tf.GIT_VERSION is deprecated. Please use tf.version.GIT_VERSION instead.

W0518 07:34:36.486817 140469935716096 deprecation_wrapper.py:119] From /data2/MECo/tensorflow_models/models-1.11/official/utils/logs/logger.py:342: The name tf.GIT_VERSION is deprecated. Please use tf.version.GIT_VERSION instead.

WARNING:tensorflow:From /data2/MECo/tensorflow_models/models-1.11/official/utils/logs/logger.py:386: The name tf.logging.warn is deprecated. Please use tf.compat.v1.logging.warn instead.

W0518 07:34:36.487330 140469935716096 deprecation_wrapper.py:119] From /data2/MECo/tensorflow_models/models-1.11/official/utils/logs/logger.py:386: The name tf.logging.warn is deprecated. Please use tf.compat.v1.logging.warn instead.

WARNING:tensorflow:'cpuinfo' not imported. CPU info will not be logged.
W0518 07:34:36.487412 140469935716096 logger.py:386] 'cpuinfo' not imported. CPU info will not be logged.
2020-05-18 07:34:36.488336: I tensorflow/core/common_runtime/gpu/gpu_device.cc:1640] Found device 0 with properties: 
name: GeForce GTX 1080 Ti major: 6 minor: 1 memoryClockRate(GHz): 1.6705
pciBusID: 0000:02:00.0
2020-05-18 07:34:36.488989: I tensorflow/core/common_runtime/gpu/gpu_device.cc:1640] Found device 1 with properties: 
name: GeForce GTX 1080 Ti major: 6 minor: 1 memoryClockRate(GHz): 1.6705
pciBusID: 0000:03:00.0
2020-05-18 07:34:36.489013: I tensorflow/stream_executor/platform/default/dso_loader.cc:42] Successfully opened dynamic library libcudart.so.10.0
2020-05-18 07:34:36.489025: I tensorflow/stream_executor/platform/default/dso_loader.cc:42] Successfully opened dynamic library libcublas.so.10.0
2020-05-18 07:34:36.489034: I tensorflow/stream_executor/platform/default/dso_loader.cc:42] Successfully opened dynamic library libcufft.so.10.0
2020-05-18 07:34:36.489042: I tensorflow/stream_executor/platform/default/dso_loader.cc:42] Successfully opened dynamic library libcurand.so.10.0
2020-05-18 07:34:36.489051: I tensorflow/stream_executor/platform/default/dso_loader.cc:42] Successfully opened dynamic library libcusolver.so.10.0
2020-05-18 07:34:36.489059: I tensorflow/stream_executor/platform/default/dso_loader.cc:42] Successfully opened dynamic library libcusparse.so.10.0
2020-05-18 07:34:36.489068: I tensorflow/stream_executor/platform/default/dso_loader.cc:42] Successfully opened dynamic library libcudnn.so.7
2020-05-18 07:34:36.491449: I tensorflow/core/common_runtime/gpu/gpu_device.cc:1763] Adding visible gpu devices: 0, 1
2020-05-18 07:34:36.491502: I tensorflow/core/common_runtime/gpu/gpu_device.cc:1181] Device interconnect StreamExecutor with strength 1 edge matrix:
2020-05-18 07:34:36.491509: I tensorflow/core/common_runtime/gpu/gpu_device.cc:1187]      0 1 
2020-05-18 07:34:36.491514: I tensorflow/core/common_runtime/gpu/gpu_device.cc:1200] 0:   N Y 
2020-05-18 07:34:36.491519: I tensorflow/core/common_runtime/gpu/gpu_device.cc:1200] 1:   Y N 
2020-05-18 07:34:36.493370: I tensorflow/core/common_runtime/gpu/gpu_device.cc:1326] Created TensorFlow device (/device:GPU:0 with 10083 MB memory) -> physical GPU (device: 0, name: GeForce GTX 1080 Ti, pci bus id: 0000:02:00.0, compute capability: 6.1)
2020-05-18 07:34:36.493989: I tensorflow/core/common_runtime/gpu/gpu_device.cc:1326] Created TensorFlow device (/device:GPU:1 with 10479 MB memory) -> physical GPU (device: 1, name: GeForce GTX 1080 Ti, pci bus id: 0000:03:00.0, compute capability: 6.1)
WARNING:tensorflow:'psutil' not imported. Memory info will not be logged.
W0518 07:34:36.494529 140469935716096 logger.py:416] 'psutil' not imported. Memory info will not be logged.
INFO:tensorflow:Benchmark run: {'model_name': 'resnet', 'dataset': {'name': 'ImageNet'}, 'machine_config': {'gpu_info': {'count': 2, 'model': 'GeForce GTX 1080 Ti'}}, 'test_id': None, 'run_date': '2020-05-18T11:34:36.486675Z', 'tensorflow_version': {'version': '1.14.0', 'git_hash': 'v1.14.0-rc1-22-gaf24dc91b5'}, 'tensorflow_environment_variables': [{'name': 'TF_ENABLE_WINOGRAD_NONFUSED', 'value': '1'}], 'run_parameters': [{'name': 'batch_size', 'long_value': 32}, {'name': 'dtype', 'string_value': "<dtype: 'float32'>"}, {'name': 'resnet_size', 'string_value': '21'}, {'name': 'resnet_version', 'string_value': '1'}, {'name': 'synthetic_data', 'bool_value': 'False'}, {'name': 'train_epochs', 'long_value': 100}]}
I0518 07:34:36.500433 140469935716096 logger.py:151] Benchmark run: {'model_name': 'resnet', 'dataset': {'name': 'ImageNet'}, 'machine_config': {'gpu_info': {'count': 2, 'model': 'GeForce GTX 1080 Ti'}}, 'test_id': None, 'run_date': '2020-05-18T11:34:36.486675Z', 'tensorflow_version': {'version': '1.14.0', 'git_hash': 'v1.14.0-rc1-22-gaf24dc91b5'}, 'tensorflow_environment_variables': [{'name': 'TF_ENABLE_WINOGRAD_NONFUSED', 'value': '1'}], 'run_parameters': [{'name': 'batch_size', 'long_value': 32}, {'name': 'dtype', 'string_value': "<dtype: 'float32'>"}, {'name': 'resnet_size', 'string_value': '21'}, {'name': 'resnet_version', 'string_value': '1'}, {'name': 'synthetic_data', 'bool_value': 'False'}, {'name': 'train_epochs', 'long_value': 100}]}
INFO:tensorflow:Starting cycle: 0/1
I0518 07:34:36.500870 140469935716096 resnet_run_loop.py:465] Starting cycle: 0/1
INFO:tensorflow:Starting to evaluate.
I0518 07:34:36.501076 140469935716096 resnet_run_loop.py:471] Starting to evaluate.
WARNING:tensorflow:From imagenet_main.py:185: parallel_interleave (from tensorflow.contrib.data.python.ops.interleave_ops) is deprecated and will be removed in a future version.
Instructions for updating:
Use `tf.data.experimental.parallel_interleave(...)`.
W0518 07:34:36.516454 140469935716096 deprecation.py:323] From imagenet_main.py:185: parallel_interleave (from tensorflow.contrib.data.python.ops.interleave_ops) is deprecated and will be removed in a future version.
Instructions for updating:
Use `tf.data.experimental.parallel_interleave(...)`.
WARNING:tensorflow:From /home/jon/anaconda3/envs/tf1.14-gpu/lib/python3.6/site-packages/tensorflow/contrib/data/python/ops/interleave_ops.py:77: parallel_interleave (from tensorflow.python.data.experimental.ops.interleave_ops) is deprecated and will be removed in a future version.
Instructions for updating:
Use `tf.data.Dataset.interleave(map_func, cycle_length, block_length, num_parallel_calls=tf.data.experimental.AUTOTUNE)` instead. If sloppy execution is desired, use `tf.data.Options.experimental_determinstic`.
W0518 07:34:36.516576 140469935716096 deprecation.py:323] From /home/jon/anaconda3/envs/tf1.14-gpu/lib/python3.6/site-packages/tensorflow/contrib/data/python/ops/interleave_ops.py:77: parallel_interleave (from tensorflow.python.data.experimental.ops.interleave_ops) is deprecated and will be removed in a future version.
Instructions for updating:
Use `tf.data.Dataset.interleave(map_func, cycle_length, block_length, num_parallel_calls=tf.data.experimental.AUTOTUNE)` instead. If sloppy execution is desired, use `tf.data.Options.experimental_determinstic`.
WARNING:tensorflow:From /data2/MECo/tensorflow_models/models-1.11/official/resnet/resnet_run_loop.py:98: map_and_batch (from tensorflow.contrib.data.python.ops.batching) is deprecated and will be removed in a future version.
Instructions for updating:
Use `tf.data.experimental.map_and_batch(...)`.
W0518 07:34:36.540163 140469935716096 deprecation.py:323] From /data2/MECo/tensorflow_models/models-1.11/official/resnet/resnet_run_loop.py:98: map_and_batch (from tensorflow.contrib.data.python.ops.batching) is deprecated and will be removed in a future version.
Instructions for updating:
Use `tf.data.experimental.map_and_batch(...)`.
WARNING:tensorflow:From /home/jon/anaconda3/envs/tf1.14-gpu/lib/python3.6/site-packages/tensorflow/contrib/data/python/ops/batching.py:273: map_and_batch (from tensorflow.python.data.experimental.ops.batching) is deprecated and will be removed in a future version.
Instructions for updating:
Use `tf.data.Dataset.map(map_func, num_parallel_calls)` followed by `tf.data.Dataset.batch(batch_size, drop_remainder)`. Static tf.data optimizations will take care of using the fused implementation.
W0518 07:34:36.540284 140469935716096 deprecation.py:323] From /home/jon/anaconda3/envs/tf1.14-gpu/lib/python3.6/site-packages/tensorflow/contrib/data/python/ops/batching.py:273: map_and_batch (from tensorflow.python.data.experimental.ops.batching) is deprecated and will be removed in a future version.
Instructions for updating:
Use `tf.data.Dataset.map(map_func, num_parallel_calls)` followed by `tf.data.Dataset.batch(batch_size, drop_remainder)`. Static tf.data optimizations will take care of using the fused implementation.
WARNING:tensorflow:From imagenet_main.py:98: The name tf.FixedLenFeature is deprecated. Please use tf.io.FixedLenFeature instead.

W0518 07:34:36.541514 140469935716096 deprecation_wrapper.py:119] From imagenet_main.py:98: The name tf.FixedLenFeature is deprecated. Please use tf.io.FixedLenFeature instead.

WARNING:tensorflow:From imagenet_main.py:105: The name tf.VarLenFeature is deprecated. Please use tf.io.VarLenFeature instead.

W0518 07:34:36.541674 140469935716096 deprecation_wrapper.py:119] From imagenet_main.py:105: The name tf.VarLenFeature is deprecated. Please use tf.io.VarLenFeature instead.

WARNING:tensorflow:From /data2/MECo/tensorflow_models/models-1.11/official/resnet/imagenet_preprocessing.py:221: The name tf.image.resize_images is deprecated. Please use tf.image.resize instead.

W0518 07:34:36.572354 140469935716096 deprecation_wrapper.py:119] From /data2/MECo/tensorflow_models/models-1.11/official/resnet/imagenet_preprocessing.py:221: The name tf.image.resize_images is deprecated. Please use tf.image.resize instead.

INFO:tensorflow:Calling model_fn.
I0518 07:34:36.611940 140469935716096 estimator.py:1145] Calling model_fn.
WARNING:tensorflow:From /data2/MECo/tensorflow_models/models-1.11/official/resnet/resnet_run_loop.py:232: The name tf.summary.image is deprecated. Please use tf.compat.v1.summary.image instead.

W0518 07:34:36.612094 140469935716096 deprecation_wrapper.py:119] From /data2/MECo/tensorflow_models/models-1.11/official/resnet/resnet_run_loop.py:232: The name tf.summary.image is deprecated. Please use tf.compat.v1.summary.image instead.

WARNING:tensorflow:From /data2/MECo/tensorflow_models/models-1.11/official/resnet/resnet_model.py:95: conv2d (from tensorflow.python.layers.convolutional) is deprecated and will be removed in a future version.
Instructions for updating:
Use `tf.keras.layers.Conv2D` instead.
W0518 07:34:36.615229 140469935716096 deprecation.py:323] From /data2/MECo/tensorflow_models/models-1.11/official/resnet/resnet_model.py:95: conv2d (from tensorflow.python.layers.convolutional) is deprecated and will be removed in a future version.
Instructions for updating:
Use `tf.keras.layers.Conv2D` instead.
WARNING:tensorflow:Entity <bound method Conv.call of <tensorflow.python.layers.convolutional.Conv2D object at 0x7fc10258a390>> could not be transformed and will be executed as-is. Please report this to the AutgoGraph team. When filing the bug, set the verbosity to 10 (on Linux, `export AUTOGRAPH_VERBOSITY=10`) and attach the full output. Cause: converting <bound method Conv.call of <tensorflow.python.layers.convolutional.Conv2D object at 0x7fc10258a390>>: AssertionError: Bad argument number for Name: 3, expecting 4
W0518 07:34:36.682724 140469935716096 ag_logging.py:145] Entity <bound method Conv.call of <tensorflow.python.layers.convolutional.Conv2D object at 0x7fc10258a390>> could not be transformed and will be executed as-is. Please report this to the AutgoGraph team. When filing the bug, set the verbosity to 10 (on Linux, `export AUTOGRAPH_VERBOSITY=10`) and attach the full output. Cause: converting <bound method Conv.call of <tensorflow.python.layers.convolutional.Conv2D object at 0x7fc10258a390>>: AssertionError: Bad argument number for Name: 3, expecting 4
WARNING:tensorflow:From /data2/MECo/tensorflow_models/models-1.11/official/resnet/resnet_model.py:54: batch_normalization (from tensorflow.python.layers.normalization) is deprecated and will be removed in a future version.
Instructions for updating:
Use keras.layers.BatchNormalization instead.  In particular, `tf.control_dependencies(tf.GraphKeys.UPDATE_OPS)` should not be used (consult the `tf.keras.layers.batch_normalization` documentation).
W0518 07:34:36.684510 140469935716096 deprecation.py:323] From /data2/MECo/tensorflow_models/models-1.11/official/resnet/resnet_model.py:54: batch_normalization (from tensorflow.python.layers.normalization) is deprecated and will be removed in a future version.
Instructions for updating:
Use keras.layers.BatchNormalization instead.  In particular, `tf.control_dependencies(tf.GraphKeys.UPDATE_OPS)` should not be used (consult the `tf.keras.layers.batch_normalization` documentation).
WARNING:tensorflow:Entity <bound method BatchNormalization.call of <tensorflow.python.layers.normalization.BatchNormalization object at 0x7fc10258a6d8>> could not be transformed and will be executed as-is. Please report this to the AutgoGraph team. When filing the bug, set the verbosity to 10 (on Linux, `export AUTOGRAPH_VERBOSITY=10`) and attach the full output. Cause: converting <bound method BatchNormalization.call of <tensorflow.python.layers.normalization.BatchNormalization object at 0x7fc10258a6d8>>: AssertionError: Bad argument number for Name: 3, expecting 4
W0518 07:34:36.709145 140469935716096 ag_logging.py:145] Entity <bound method BatchNormalization.call of <tensorflow.python.layers.normalization.BatchNormalization object at 0x7fc10258a6d8>> could not be transformed and will be executed as-is. Please report this to the AutgoGraph team. When filing the bug, set the verbosity to 10 (on Linux, `export AUTOGRAPH_VERBOSITY=10`) and attach the full output. Cause: converting <bound method BatchNormalization.call of <tensorflow.python.layers.normalization.BatchNormalization object at 0x7fc10258a6d8>>: AssertionError: Bad argument number for Name: 3, expecting 4
WARNING:tensorflow:From /data2/MECo/tensorflow_models/models-1.11/official/resnet/resnet_model.py:519: max_pooling2d (from tensorflow.python.layers.pooling) is deprecated and will be removed in a future version.
Instructions for updating:
Use keras.layers.MaxPooling2D instead.
W0518 07:34:36.711220 140469935716096 deprecation.py:323] From /data2/MECo/tensorflow_models/models-1.11/official/resnet/resnet_model.py:519: max_pooling2d (from tensorflow.python.layers.pooling) is deprecated and will be removed in a future version.
Instructions for updating:
Use keras.layers.MaxPooling2D instead.
WARNING:tensorflow:Entity <bound method Pooling2D.call of <tensorflow.python.layers.pooling.MaxPooling2D object at 0x7fc10258a6d8>> could not be transformed and will be executed as-is. Please report this to the AutgoGraph team. When filing the bug, set the verbosity to 10 (on Linux, `export AUTOGRAPH_VERBOSITY=10`) and attach the full output. Cause: converting <bound method Pooling2D.call of <tensorflow.python.layers.pooling.MaxPooling2D object at 0x7fc10258a6d8>>: AssertionError: Bad argument number for Name: 3, expecting 4
W0518 07:34:36.749070 140469935716096 ag_logging.py:145] Entity <bound method Pooling2D.call of <tensorflow.python.layers.pooling.MaxPooling2D object at 0x7fc10258a6d8>> could not be transformed and will be executed as-is. Please report this to the AutgoGraph team. When filing the bug, set the verbosity to 10 (on Linux, `export AUTOGRAPH_VERBOSITY=10`) and attach the full output. Cause: converting <bound method Pooling2D.call of <tensorflow.python.layers.pooling.MaxPooling2D object at 0x7fc10258a6d8>>: AssertionError: Bad argument number for Name: 3, expecting 4
WARNING:tensorflow:Entity <bound method Conv.call of <tensorflow.python.layers.convolutional.Conv2D object at 0x7fc1025e7160>> could not be transformed and will be executed as-is. Please report this to the AutgoGraph team. When filing the bug, set the verbosity to 10 (on Linux, `export AUTOGRAPH_VERBOSITY=10`) and attach the full output. Cause: converting <bound method Conv.call of <tensorflow.python.layers.convolutional.Conv2D object at 0x7fc1025e7160>>: AssertionError: Bad argument number for Name: 3, expecting 4
W0518 07:34:36.807781 140469935716096 ag_logging.py:145] Entity <bound method Conv.call of <tensorflow.python.layers.convolutional.Conv2D object at 0x7fc1025e7160>> could not be transformed and will be executed as-is. Please report this to the AutgoGraph team. When filing the bug, set the verbosity to 10 (on Linux, `export AUTOGRAPH_VERBOSITY=10`) and attach the full output. Cause: converting <bound method Conv.call of <tensorflow.python.layers.convolutional.Conv2D object at 0x7fc1025e7160>>: AssertionError: Bad argument number for Name: 3, expecting 4
WARNING:tensorflow:Entity <bound method BatchNormalization.call of <tensorflow.python.layers.normalization.BatchNormalization object at 0x7fc10258a390>> could not be transformed and will be executed as-is. Please report this to the AutgoGraph team. When filing the bug, set the verbosity to 10 (on Linux, `export AUTOGRAPH_VERBOSITY=10`) and attach the full output. Cause: converting <bound method BatchNormalization.call of <tensorflow.python.layers.normalization.BatchNormalization object at 0x7fc10258a390>>: AssertionError: Bad argument number for Name: 3, expecting 4
W0518 07:34:36.832841 140469935716096 ag_logging.py:145] Entity <bound method BatchNormalization.call of <tensorflow.python.layers.normalization.BatchNormalization object at 0x7fc10258a390>> could not be transformed and will be executed as-is. Please report this to the AutgoGraph team. When filing the bug, set the verbosity to 10 (on Linux, `export AUTOGRAPH_VERBOSITY=10`) and attach the full output. Cause: converting <bound method BatchNormalization.call of <tensorflow.python.layers.normalization.BatchNormalization object at 0x7fc10258a390>>: AssertionError: Bad argument number for Name: 3, expecting 4
WARNING:tensorflow:Entity <bound method Conv.call of <tensorflow.python.layers.convolutional.Conv2D object at 0x7fc1025e7160>> could not be transformed and will be executed as-is. Please report this to the AutgoGraph team. When filing the bug, set the verbosity to 10 (on Linux, `export AUTOGRAPH_VERBOSITY=10`) and attach the full output. Cause: converting <bound method Conv.call of <tensorflow.python.layers.convolutional.Conv2D object at 0x7fc1025e7160>>: AssertionError: Bad argument number for Name: 3, expecting 4
W0518 07:34:36.891342 140469935716096 ag_logging.py:145] Entity <bound method Conv.call of <tensorflow.python.layers.convolutional.Conv2D object at 0x7fc1025e7160>> could not be transformed and will be executed as-is. Please report this to the AutgoGraph team. When filing the bug, set the verbosity to 10 (on Linux, `export AUTOGRAPH_VERBOSITY=10`) and attach the full output. Cause: converting <bound method Conv.call of <tensorflow.python.layers.convolutional.Conv2D object at 0x7fc1025e7160>>: AssertionError: Bad argument number for Name: 3, expecting 4
WARNING:tensorflow:Entity <bound method BatchNormalization.call of <tensorflow.python.layers.normalization.BatchNormalization object at 0x7fc10258a390>> could not be transformed and will be executed as-is. Please report this to the AutgoGraph team. When filing the bug, set the verbosity to 10 (on Linux, `export AUTOGRAPH_VERBOSITY=10`) and attach the full output. Cause: converting <bound method BatchNormalization.call of <tensorflow.python.layers.normalization.BatchNormalization object at 0x7fc10258a390>>: AssertionError: Bad argument number for Name: 3, expecting 4
W0518 07:34:36.958446 140469935716096 ag_logging.py:145] Entity <bound method BatchNormalization.call of <tensorflow.python.layers.normalization.BatchNormalization object at 0x7fc10258a390>> could not be transformed and will be executed as-is. Please report this to the AutgoGraph team. When filing the bug, set the verbosity to 10 (on Linux, `export AUTOGRAPH_VERBOSITY=10`) and attach the full output. Cause: converting <bound method BatchNormalization.call of <tensorflow.python.layers.normalization.BatchNormalization object at 0x7fc10258a390>>: AssertionError: Bad argument number for Name: 3, expecting 4
WARNING:tensorflow:Entity <bound method Conv.call of <tensorflow.python.layers.convolutional.Conv2D object at 0x7fc1af93c588>> could not be transformed and will be executed as-is. Please report this to the AutgoGraph team. When filing the bug, set the verbosity to 10 (on Linux, `export AUTOGRAPH_VERBOSITY=10`) and attach the full output. Cause: converting <bound method Conv.call of <tensorflow.python.layers.convolutional.Conv2D object at 0x7fc1af93c588>>: AssertionError: Bad argument number for Name: 3, expecting 4
W0518 07:34:37.019443 140469935716096 ag_logging.py:145] Entity <bound method Conv.call of <tensorflow.python.layers.convolutional.Conv2D object at 0x7fc1af93c588>> could not be transformed and will be executed as-is. Please report this to the AutgoGraph team. When filing the bug, set the verbosity to 10 (on Linux, `export AUTOGRAPH_VERBOSITY=10`) and attach the full output. Cause: converting <bound method Conv.call of <tensorflow.python.layers.convolutional.Conv2D object at 0x7fc1af93c588>>: AssertionError: Bad argument number for Name: 3, expecting 4
WARNING:tensorflow:Entity <bound method BatchNormalization.call of <tensorflow.python.layers.normalization.BatchNormalization object at 0x7fc10258a390>> could not be transformed and will be executed as-is. Please report this to the AutgoGraph team. When filing the bug, set the verbosity to 10 (on Linux, `export AUTOGRAPH_VERBOSITY=10`) and attach the full output. Cause: converting <bound method BatchNormalization.call of <tensorflow.python.layers.normalization.BatchNormalization object at 0x7fc10258a390>>: AssertionError: Bad argument number for Name: 3, expecting 4
W0518 07:34:37.045170 140469935716096 ag_logging.py:145] Entity <bound method BatchNormalization.call of <tensorflow.python.layers.normalization.BatchNormalization object at 0x7fc10258a390>> could not be transformed and will be executed as-is. Please report this to the AutgoGraph team. When filing the bug, set the verbosity to 10 (on Linux, `export AUTOGRAPH_VERBOSITY=10`) and attach the full output. Cause: converting <bound method BatchNormalization.call of <tensorflow.python.layers.normalization.BatchNormalization object at 0x7fc10258a390>>: AssertionError: Bad argument number for Name: 3, expecting 4
WARNING:tensorflow:Entity <bound method Conv.call of <tensorflow.python.layers.convolutional.Conv2D object at 0x7fc102452358>> could not be transformed and will be executed as-is. Please report this to the AutgoGraph team. When filing the bug, set the verbosity to 10 (on Linux, `export AUTOGRAPH_VERBOSITY=10`) and attach the full output. Cause: converting <bound method Conv.call of <tensorflow.python.layers.convolutional.Conv2D object at 0x7fc102452358>>: AssertionError: Bad argument number for Name: 3, expecting 4
W0518 07:34:37.104893 140469935716096 ag_logging.py:145] Entity <bound method Conv.call of <tensorflow.python.layers.convolutional.Conv2D object at 0x7fc102452358>> could not be transformed and will be executed as-is. Please report this to the AutgoGraph team. When filing the bug, set the verbosity to 10 (on Linux, `export AUTOGRAPH_VERBOSITY=10`) and attach the full output. Cause: converting <bound method Conv.call of <tensorflow.python.layers.convolutional.Conv2D object at 0x7fc102452358>>: AssertionError: Bad argument number for Name: 3, expecting 4
WARNING:tensorflow:Entity <bound method BatchNormalization.call of <tensorflow.python.layers.normalization.BatchNormalization object at 0x7fc10258a390>> could not be transformed and will be executed as-is. Please report this to the AutgoGraph team. When filing the bug, set the verbosity to 10 (on Linux, `export AUTOGRAPH_VERBOSITY=10`) and attach the full output. Cause: converting <bound method BatchNormalization.call of <tensorflow.python.layers.normalization.BatchNormalization object at 0x7fc10258a390>>: AssertionError: Bad argument number for Name: 3, expecting 4
W0518 07:34:37.130407 140469935716096 ag_logging.py:145] Entity <bound method BatchNormalization.call of <tensorflow.python.layers.normalization.BatchNormalization object at 0x7fc10258a390>> could not be transformed and will be executed as-is. Please report this to the AutgoGraph team. When filing the bug, set the verbosity to 10 (on Linux, `export AUTOGRAPH_VERBOSITY=10`) and attach the full output. Cause: converting <bound method BatchNormalization.call of <tensorflow.python.layers.normalization.BatchNormalization object at 0x7fc10258a390>>: AssertionError: Bad argument number for Name: 3, expecting 4
WARNING:tensorflow:Entity <bound method Conv.call of <tensorflow.python.layers.convolutional.Conv2D object at 0x7fc102452358>> could not be transformed and will be executed as-is. Please report this to the AutgoGraph team. When filing the bug, set the verbosity to 10 (on Linux, `export AUTOGRAPH_VERBOSITY=10`) and attach the full output. Cause: converting <bound method Conv.call of <tensorflow.python.layers.convolutional.Conv2D object at 0x7fc102452358>>: AssertionError: Bad argument number for Name: 3, expecting 4
W0518 07:34:37.189255 140469935716096 ag_logging.py:145] Entity <bound method Conv.call of <tensorflow.python.layers.convolutional.Conv2D object at 0x7fc102452358>> could not be transformed and will be executed as-is. Please report this to the AutgoGraph team. When filing the bug, set the verbosity to 10 (on Linux, `export AUTOGRAPH_VERBOSITY=10`) and attach the full output. Cause: converting <bound method Conv.call of <tensorflow.python.layers.convolutional.Conv2D object at 0x7fc102452358>>: AssertionError: Bad argument number for Name: 3, expecting 4
WARNING:tensorflow:Entity <bound method BatchNormalization.call of <tensorflow.python.layers.normalization.BatchNormalization object at 0x7fc10258a390>> could not be transformed and will be executed as-is. Please report this to the AutgoGraph team. When filing the bug, set the verbosity to 10 (on Linux, `export AUTOGRAPH_VERBOSITY=10`) and attach the full output. Cause: converting <bound method BatchNormalization.call of <tensorflow.python.layers.normalization.BatchNormalization object at 0x7fc10258a390>>: AssertionError: Bad argument number for Name: 3, expecting 4
W0518 07:34:37.214571 140469935716096 ag_logging.py:145] Entity <bound method BatchNormalization.call of <tensorflow.python.layers.normalization.BatchNormalization object at 0x7fc10258a390>> could not be transformed and will be executed as-is. Please report this to the AutgoGraph team. When filing the bug, set the verbosity to 10 (on Linux, `export AUTOGRAPH_VERBOSITY=10`) and attach the full output. Cause: converting <bound method BatchNormalization.call of <tensorflow.python.layers.normalization.BatchNormalization object at 0x7fc10258a390>>: AssertionError: Bad argument number for Name: 3, expecting 4
WARNING:tensorflow:Entity <bound method Conv.call of <tensorflow.python.layers.convolutional.Conv2D object at 0x7fc102349198>> could not be transformed and will be executed as-is. Please report this to the AutgoGraph team. When filing the bug, set the verbosity to 10 (on Linux, `export AUTOGRAPH_VERBOSITY=10`) and attach the full output. Cause: converting <bound method Conv.call of <tensorflow.python.layers.convolutional.Conv2D object at 0x7fc102349198>>: AssertionError: Bad argument number for Name: 3, expecting 4
W0518 07:34:37.276520 140469935716096 ag_logging.py:145] Entity <bound method Conv.call of <tensorflow.python.layers.convolutional.Conv2D object at 0x7fc102349198>> could not be transformed and will be executed as-is. Please report this to the AutgoGraph team. When filing the bug, set the verbosity to 10 (on Linux, `export AUTOGRAPH_VERBOSITY=10`) and attach the full output. Cause: converting <bound method Conv.call of <tensorflow.python.layers.convolutional.Conv2D object at 0x7fc102349198>>: AssertionError: Bad argument number for Name: 3, expecting 4
WARNING:tensorflow:Entity <bound method BatchNormalization.call of <tensorflow.python.layers.normalization.BatchNormalization object at 0x7fc10238b400>> could not be transformed and will be executed as-is. Please report this to the AutgoGraph team. When filing the bug, set the verbosity to 10 (on Linux, `export AUTOGRAPH_VERBOSITY=10`) and attach the full output. Cause: converting <bound method BatchNormalization.call of <tensorflow.python.layers.normalization.BatchNormalization object at 0x7fc10238b400>>: AssertionError: Bad argument number for Name: 3, expecting 4
W0518 07:34:37.301784 140469935716096 ag_logging.py:145] Entity <bound method BatchNormalization.call of <tensorflow.python.layers.normalization.BatchNormalization object at 0x7fc10238b400>> could not be transformed and will be executed as-is. Please report this to the AutgoGraph team. When filing the bug, set the verbosity to 10 (on Linux, `export AUTOGRAPH_VERBOSITY=10`) and attach the full output. Cause: converting <bound method BatchNormalization.call of <tensorflow.python.layers.normalization.BatchNormalization object at 0x7fc10238b400>>: AssertionError: Bad argument number for Name: 3, expecting 4
WARNING:tensorflow:Entity <bound method Conv.call of <tensorflow.python.layers.convolutional.Conv2D object at 0x7fc102349ba8>> could not be transformed and will be executed as-is. Please report this to the AutgoGraph team. When filing the bug, set the verbosity to 10 (on Linux, `export AUTOGRAPH_VERBOSITY=10`) and attach the full output. Cause: converting <bound method Conv.call of <tensorflow.python.layers.convolutional.Conv2D object at 0x7fc102349ba8>>: AssertionError: Bad argument number for Name: 3, expecting 4
W0518 07:34:37.361260 140469935716096 ag_logging.py:145] Entity <bound method Conv.call of <tensorflow.python.layers.convolutional.Conv2D object at 0x7fc102349ba8>> could not be transformed and will be executed as-is. Please report this to the AutgoGraph team. When filing the bug, set the verbosity to 10 (on Linux, `export AUTOGRAPH_VERBOSITY=10`) and attach the full output. Cause: converting <bound method Conv.call of <tensorflow.python.layers.convolutional.Conv2D object at 0x7fc102349ba8>>: AssertionError: Bad argument number for Name: 3, expecting 4
WARNING:tensorflow:Entity <bound method BatchNormalization.call of <tensorflow.python.layers.normalization.BatchNormalization object at 0x7fc1023490b8>> could not be transformed and will be executed as-is. Please report this to the AutgoGraph team. When filing the bug, set the verbosity to 10 (on Linux, `export AUTOGRAPH_VERBOSITY=10`) and attach the full output. Cause: converting <bound method BatchNormalization.call of <tensorflow.python.layers.normalization.BatchNormalization object at 0x7fc1023490b8>>: AssertionError: Bad argument number for Name: 3, expecting 4
W0518 07:34:37.386188 140469935716096 ag_logging.py:145] Entity <bound method BatchNormalization.call of <tensorflow.python.layers.normalization.BatchNormalization object at 0x7fc1023490b8>> could not be transformed and will be executed as-is. Please report this to the AutgoGraph team. When filing the bug, set the verbosity to 10 (on Linux, `export AUTOGRAPH_VERBOSITY=10`) and attach the full output. Cause: converting <bound method BatchNormalization.call of <tensorflow.python.layers.normalization.BatchNormalization object at 0x7fc1023490b8>>: AssertionError: Bad argument number for Name: 3, expecting 4
WARNING:tensorflow:Entity <bound method Conv.call of <tensorflow.python.layers.convolutional.Conv2D object at 0x7fc102349ba8>> could not be transformed and will be executed as-is. Please report this to the AutgoGraph team. When filing the bug, set the verbosity to 10 (on Linux, `export AUTOGRAPH_VERBOSITY=10`) and attach the full output. Cause: converting <bound method Conv.call of <tensorflow.python.layers.convolutional.Conv2D object at 0x7fc102349ba8>>: AssertionError: Bad argument number for Name: 3, expecting 4
W0518 07:34:37.444523 140469935716096 ag_logging.py:145] Entity <bound method Conv.call of <tensorflow.python.layers.convolutional.Conv2D object at 0x7fc102349ba8>> could not be transformed and will be executed as-is. Please report this to the AutgoGraph team. When filing the bug, set the verbosity to 10 (on Linux, `export AUTOGRAPH_VERBOSITY=10`) and attach the full output. Cause: converting <bound method Conv.call of <tensorflow.python.layers.convolutional.Conv2D object at 0x7fc102349ba8>>: AssertionError: Bad argument number for Name: 3, expecting 4
WARNING:tensorflow:Entity <bound method BatchNormalization.call of <tensorflow.python.layers.normalization.BatchNormalization object at 0x7fc1023490b8>> could not be transformed and will be executed as-is. Please report this to the AutgoGraph team. When filing the bug, set the verbosity to 10 (on Linux, `export AUTOGRAPH_VERBOSITY=10`) and attach the full output. Cause: converting <bound method BatchNormalization.call of <tensorflow.python.layers.normalization.BatchNormalization object at 0x7fc1023490b8>>: AssertionError: Bad argument number for Name: 3, expecting 4
W0518 07:34:37.469077 140469935716096 ag_logging.py:145] Entity <bound method BatchNormalization.call of <tensorflow.python.layers.normalization.BatchNormalization object at 0x7fc1023490b8>> could not be transformed and will be executed as-is. Please report this to the AutgoGraph team. When filing the bug, set the verbosity to 10 (on Linux, `export AUTOGRAPH_VERBOSITY=10`) and attach the full output. Cause: converting <bound method BatchNormalization.call of <tensorflow.python.layers.normalization.BatchNormalization object at 0x7fc1023490b8>>: AssertionError: Bad argument number for Name: 3, expecting 4
WARNING:tensorflow:Entity <bound method Conv.call of <tensorflow.python.layers.convolutional.Conv2D object at 0x7fc1023490b8>> could not be transformed and will be executed as-is. Please report this to the AutgoGraph team. When filing the bug, set the verbosity to 10 (on Linux, `export AUTOGRAPH_VERBOSITY=10`) and attach the full output. Cause: converting <bound method Conv.call of <tensorflow.python.layers.convolutional.Conv2D object at 0x7fc1023490b8>>: AssertionError: Bad argument number for Name: 3, expecting 4
W0518 07:34:37.527680 140469935716096 ag_logging.py:145] Entity <bound method Conv.call of <tensorflow.python.layers.convolutional.Conv2D object at 0x7fc1023490b8>> could not be transformed and will be executed as-is. Please report this to the AutgoGraph team. When filing the bug, set the verbosity to 10 (on Linux, `export AUTOGRAPH_VERBOSITY=10`) and attach the full output. Cause: converting <bound method Conv.call of <tensorflow.python.layers.convolutional.Conv2D object at 0x7fc1023490b8>>: AssertionError: Bad argument number for Name: 3, expecting 4
WARNING:tensorflow:Entity <bound method BatchNormalization.call of <tensorflow.python.layers.normalization.BatchNormalization object at 0x7fc1025d6e80>> could not be transformed and will be executed as-is. Please report this to the AutgoGraph team. When filing the bug, set the verbosity to 10 (on Linux, `export AUTOGRAPH_VERBOSITY=10`) and attach the full output. Cause: converting <bound method BatchNormalization.call of <tensorflow.python.layers.normalization.BatchNormalization object at 0x7fc1025d6e80>>: AssertionError: Bad argument number for Name: 3, expecting 4
W0518 07:34:37.552552 140469935716096 ag_logging.py:145] Entity <bound method BatchNormalization.call of <tensorflow.python.layers.normalization.BatchNormalization object at 0x7fc1025d6e80>> could not be transformed and will be executed as-is. Please report this to the AutgoGraph team. When filing the bug, set the verbosity to 10 (on Linux, `export AUTOGRAPH_VERBOSITY=10`) and attach the full output. Cause: converting <bound method BatchNormalization.call of <tensorflow.python.layers.normalization.BatchNormalization object at 0x7fc1025d6e80>>: AssertionError: Bad argument number for Name: 3, expecting 4
WARNING:tensorflow:Entity <bound method Conv.call of <tensorflow.python.layers.convolutional.Conv2D object at 0x7fc102408a90>> could not be transformed and will be executed as-is. Please report this to the AutgoGraph team. When filing the bug, set the verbosity to 10 (on Linux, `export AUTOGRAPH_VERBOSITY=10`) and attach the full output. Cause: converting <bound method Conv.call of <tensorflow.python.layers.convolutional.Conv2D object at 0x7fc102408a90>>: AssertionError: Bad argument number for Name: 3, expecting 4
W0518 07:34:37.612984 140469935716096 ag_logging.py:145] Entity <bound method Conv.call of <tensorflow.python.layers.convolutional.Conv2D object at 0x7fc102408a90>> could not be transformed and will be executed as-is. Please report this to the AutgoGraph team. When filing the bug, set the verbosity to 10 (on Linux, `export AUTOGRAPH_VERBOSITY=10`) and attach the full output. Cause: converting <bound method Conv.call of <tensorflow.python.layers.convolutional.Conv2D object at 0x7fc102408a90>>: AssertionError: Bad argument number for Name: 3, expecting 4
WARNING:tensorflow:Entity <bound method BatchNormalization.call of <tensorflow.python.layers.normalization.BatchNormalization object at 0x7fc1025d6e80>> could not be transformed and will be executed as-is. Please report this to the AutgoGraph team. When filing the bug, set the verbosity to 10 (on Linux, `export AUTOGRAPH_VERBOSITY=10`) and attach the full output. Cause: converting <bound method BatchNormalization.call of <tensorflow.python.layers.normalization.BatchNormalization object at 0x7fc1025d6e80>>: AssertionError: Bad argument number for Name: 3, expecting 4
W0518 07:34:37.637585 140469935716096 ag_logging.py:145] Entity <bound method BatchNormalization.call of <tensorflow.python.layers.normalization.BatchNormalization object at 0x7fc1025d6e80>> could not be transformed and will be executed as-is. Please report this to the AutgoGraph team. When filing the bug, set the verbosity to 10 (on Linux, `export AUTOGRAPH_VERBOSITY=10`) and attach the full output. Cause: converting <bound method BatchNormalization.call of <tensorflow.python.layers.normalization.BatchNormalization object at 0x7fc1025d6e80>>: AssertionError: Bad argument number for Name: 3, expecting 4
WARNING:tensorflow:Entity <bound method Conv.call of <tensorflow.python.layers.convolutional.Conv2D object at 0x7fc102349ba8>> could not be transformed and will be executed as-is. Please report this to the AutgoGraph team. When filing the bug, set the verbosity to 10 (on Linux, `export AUTOGRAPH_VERBOSITY=10`) and attach the full output. Cause: converting <bound method Conv.call of <tensorflow.python.layers.convolutional.Conv2D object at 0x7fc102349ba8>>: AssertionError: Bad argument number for Name: 3, expecting 4
W0518 07:34:37.696764 140469935716096 ag_logging.py:145] Entity <bound method Conv.call of <tensorflow.python.layers.convolutional.Conv2D object at 0x7fc102349ba8>> could not be transformed and will be executed as-is. Please report this to the AutgoGraph team. When filing the bug, set the verbosity to 10 (on Linux, `export AUTOGRAPH_VERBOSITY=10`) and attach the full output. Cause: converting <bound method Conv.call of <tensorflow.python.layers.convolutional.Conv2D object at 0x7fc102349ba8>>: AssertionError: Bad argument number for Name: 3, expecting 4
WARNING:tensorflow:Entity <bound method BatchNormalization.call of <tensorflow.python.layers.normalization.BatchNormalization object at 0x7fc1025d6e80>> could not be transformed and will be executed as-is. Please report this to the AutgoGraph team. When filing the bug, set the verbosity to 10 (on Linux, `export AUTOGRAPH_VERBOSITY=10`) and attach the full output. Cause: converting <bound method BatchNormalization.call of <tensorflow.python.layers.normalization.BatchNormalization object at 0x7fc1025d6e80>>: AssertionError: Bad argument number for Name: 3, expecting 4
W0518 07:34:37.721357 140469935716096 ag_logging.py:145] Entity <bound method BatchNormalization.call of <tensorflow.python.layers.normalization.BatchNormalization object at 0x7fc1025d6e80>> could not be transformed and will be executed as-is. Please report this to the AutgoGraph team. When filing the bug, set the verbosity to 10 (on Linux, `export AUTOGRAPH_VERBOSITY=10`) and attach the full output. Cause: converting <bound method BatchNormalization.call of <tensorflow.python.layers.normalization.BatchNormalization object at 0x7fc1025d6e80>>: AssertionError: Bad argument number for Name: 3, expecting 4
WARNING:tensorflow:Entity <bound method Conv.call of <tensorflow.python.layers.convolutional.Conv2D object at 0x7fc102349ba8>> could not be transformed and will be executed as-is. Please report this to the AutgoGraph team. When filing the bug, set the verbosity to 10 (on Linux, `export AUTOGRAPH_VERBOSITY=10`) and attach the full output. Cause: converting <bound method Conv.call of <tensorflow.python.layers.convolutional.Conv2D object at 0x7fc102349ba8>>: AssertionError: Bad argument number for Name: 3, expecting 4
W0518 07:34:37.779474 140469935716096 ag_logging.py:145] Entity <bound method Conv.call of <tensorflow.python.layers.convolutional.Conv2D object at 0x7fc102349ba8>> could not be transformed and will be executed as-is. Please report this to the AutgoGraph team. When filing the bug, set the verbosity to 10 (on Linux, `export AUTOGRAPH_VERBOSITY=10`) and attach the full output. Cause: converting <bound method Conv.call of <tensorflow.python.layers.convolutional.Conv2D object at 0x7fc102349ba8>>: AssertionError: Bad argument number for Name: 3, expecting 4
WARNING:tensorflow:Entity <bound method BatchNormalization.call of <tensorflow.python.layers.normalization.BatchNormalization object at 0x7fc102408a90>> could not be transformed and will be executed as-is. Please report this to the AutgoGraph team. When filing the bug, set the verbosity to 10 (on Linux, `export AUTOGRAPH_VERBOSITY=10`) and attach the full output. Cause: converting <bound method BatchNormalization.call of <tensorflow.python.layers.normalization.BatchNormalization object at 0x7fc102408a90>>: AssertionError: Bad argument number for Name: 3, expecting 4
W0518 07:34:37.804290 140469935716096 ag_logging.py:145] Entity <bound method BatchNormalization.call of <tensorflow.python.layers.normalization.BatchNormalization object at 0x7fc102408a90>> could not be transformed and will be executed as-is. Please report this to the AutgoGraph team. When filing the bug, set the verbosity to 10 (on Linux, `export AUTOGRAPH_VERBOSITY=10`) and attach the full output. Cause: converting <bound method BatchNormalization.call of <tensorflow.python.layers.normalization.BatchNormalization object at 0x7fc102408a90>>: AssertionError: Bad argument number for Name: 3, expecting 4
WARNING:tensorflow:Entity <bound method Conv.call of <tensorflow.python.layers.convolutional.Conv2D object at 0x7fc102181c18>> could not be transformed and will be executed as-is. Please report this to the AutgoGraph team. When filing the bug, set the verbosity to 10 (on Linux, `export AUTOGRAPH_VERBOSITY=10`) and attach the full output. Cause: converting <bound method Conv.call of <tensorflow.python.layers.convolutional.Conv2D object at 0x7fc102181c18>>: AssertionError: Bad argument number for Name: 3, expecting 4
W0518 07:34:37.865469 140469935716096 ag_logging.py:145] Entity <bound method Conv.call of <tensorflow.python.layers.convolutional.Conv2D object at 0x7fc102181c18>> could not be transformed and will be executed as-is. Please report this to the AutgoGraph team. When filing the bug, set the verbosity to 10 (on Linux, `export AUTOGRAPH_VERBOSITY=10`) and attach the full output. Cause: converting <bound method Conv.call of <tensorflow.python.layers.convolutional.Conv2D object at 0x7fc102181c18>>: AssertionError: Bad argument number for Name: 3, expecting 4
WARNING:tensorflow:Entity <bound method BatchNormalization.call of <tensorflow.python.layers.normalization.BatchNormalization object at 0x7fc1021ded30>> could not be transformed and will be executed as-is. Please report this to the AutgoGraph team. When filing the bug, set the verbosity to 10 (on Linux, `export AUTOGRAPH_VERBOSITY=10`) and attach the full output. Cause: converting <bound method BatchNormalization.call of <tensorflow.python.layers.normalization.BatchNormalization object at 0x7fc1021ded30>>: AssertionError: Bad argument number for Name: 3, expecting 4
W0518 07:34:37.890111 140469935716096 ag_logging.py:145] Entity <bound method BatchNormalization.call of <tensorflow.python.layers.normalization.BatchNormalization object at 0x7fc1021ded30>> could not be transformed and will be executed as-is. Please report this to the AutgoGraph team. When filing the bug, set the verbosity to 10 (on Linux, `export AUTOGRAPH_VERBOSITY=10`) and attach the full output. Cause: converting <bound method BatchNormalization.call of <tensorflow.python.layers.normalization.BatchNormalization object at 0x7fc1021ded30>>: AssertionError: Bad argument number for Name: 3, expecting 4
WARNING:tensorflow:Entity <bound method Conv.call of <tensorflow.python.layers.convolutional.Conv2D object at 0x7fc10217b668>> could not be transformed and will be executed as-is. Please report this to the AutgoGraph team. When filing the bug, set the verbosity to 10 (on Linux, `export AUTOGRAPH_VERBOSITY=10`) and attach the full output. Cause: converting <bound method Conv.call of <tensorflow.python.layers.convolutional.Conv2D object at 0x7fc10217b668>>: AssertionError: Bad argument number for Name: 3, expecting 4
W0518 07:34:37.949534 140469935716096 ag_logging.py:145] Entity <bound method Conv.call of <tensorflow.python.layers.convolutional.Conv2D object at 0x7fc10217b668>> could not be transformed and will be executed as-is. Please report this to the AutgoGraph team. When filing the bug, set the verbosity to 10 (on Linux, `export AUTOGRAPH_VERBOSITY=10`) and attach the full output. Cause: converting <bound method Conv.call of <tensorflow.python.layers.convolutional.Conv2D object at 0x7fc10217b668>>: AssertionError: Bad argument number for Name: 3, expecting 4
WARNING:tensorflow:Entity <bound method BatchNormalization.call of <tensorflow.python.layers.normalization.BatchNormalization object at 0x7fc102226cf8>> could not be transformed and will be executed as-is. Please report this to the AutgoGraph team. When filing the bug, set the verbosity to 10 (on Linux, `export AUTOGRAPH_VERBOSITY=10`) and attach the full output. Cause: converting <bound method BatchNormalization.call of <tensorflow.python.layers.normalization.BatchNormalization object at 0x7fc102226cf8>>: AssertionError: Bad argument number for Name: 3, expecting 4
W0518 07:34:37.974074 140469935716096 ag_logging.py:145] Entity <bound method BatchNormalization.call of <tensorflow.python.layers.normalization.BatchNormalization object at 0x7fc102226cf8>> could not be transformed and will be executed as-is. Please report this to the AutgoGraph team. When filing the bug, set the verbosity to 10 (on Linux, `export AUTOGRAPH_VERBOSITY=10`) and attach the full output. Cause: converting <bound method BatchNormalization.call of <tensorflow.python.layers.normalization.BatchNormalization object at 0x7fc102226cf8>>: AssertionError: Bad argument number for Name: 3, expecting 4
WARNING:tensorflow:Entity <bound method Conv.call of <tensorflow.python.layers.convolutional.Conv2D object at 0x7fc10217b668>> could not be transformed and will be executed as-is. Please report this to the AutgoGraph team. When filing the bug, set the verbosity to 10 (on Linux, `export AUTOGRAPH_VERBOSITY=10`) and attach the full output. Cause: converting <bound method Conv.call of <tensorflow.python.layers.convolutional.Conv2D object at 0x7fc10217b668>>: AssertionError: Bad argument number for Name: 3, expecting 4
W0518 07:34:38.032228 140469935716096 ag_logging.py:145] Entity <bound method Conv.call of <tensorflow.python.layers.convolutional.Conv2D object at 0x7fc10217b668>> could not be transformed and will be executed as-is. Please report this to the AutgoGraph team. When filing the bug, set the verbosity to 10 (on Linux, `export AUTOGRAPH_VERBOSITY=10`) and attach the full output. Cause: converting <bound method Conv.call of <tensorflow.python.layers.convolutional.Conv2D object at 0x7fc10217b668>>: AssertionError: Bad argument number for Name: 3, expecting 4
WARNING:tensorflow:Entity <bound method BatchNormalization.call of <tensorflow.python.layers.normalization.BatchNormalization object at 0x7fc102226cf8>> could not be transformed and will be executed as-is. Please report this to the AutgoGraph team. When filing the bug, set the verbosity to 10 (on Linux, `export AUTOGRAPH_VERBOSITY=10`) and attach the full output. Cause: converting <bound method BatchNormalization.call of <tensorflow.python.layers.normalization.BatchNormalization object at 0x7fc102226cf8>>: AssertionError: Bad argument number for Name: 3, expecting 4
W0518 07:34:38.056903 140469935716096 ag_logging.py:145] Entity <bound method BatchNormalization.call of <tensorflow.python.layers.normalization.BatchNormalization object at 0x7fc102226cf8>> could not be transformed and will be executed as-is. Please report this to the AutgoGraph team. When filing the bug, set the verbosity to 10 (on Linux, `export AUTOGRAPH_VERBOSITY=10`) and attach the full output. Cause: converting <bound method BatchNormalization.call of <tensorflow.python.layers.normalization.BatchNormalization object at 0x7fc102226cf8>>: AssertionError: Bad argument number for Name: 3, expecting 4
WARNING:tensorflow:Entity <bound method Conv.call of <tensorflow.python.layers.convolutional.Conv2D object at 0x7fc1021f7978>> could not be transformed and will be executed as-is. Please report this to the AutgoGraph team. When filing the bug, set the verbosity to 10 (on Linux, `export AUTOGRAPH_VERBOSITY=10`) and attach the full output. Cause: converting <bound method Conv.call of <tensorflow.python.layers.convolutional.Conv2D object at 0x7fc1021f7978>>: AssertionError: Bad argument number for Name: 3, expecting 4
W0518 07:34:38.115187 140469935716096 ag_logging.py:145] Entity <bound method Conv.call of <tensorflow.python.layers.convolutional.Conv2D object at 0x7fc1021f7978>> could not be transformed and will be executed as-is. Please report this to the AutgoGraph team. When filing the bug, set the verbosity to 10 (on Linux, `export AUTOGRAPH_VERBOSITY=10`) and attach the full output. Cause: converting <bound method Conv.call of <tensorflow.python.layers.convolutional.Conv2D object at 0x7fc1021f7978>>: AssertionError: Bad argument number for Name: 3, expecting 4
WARNING:tensorflow:Entity <bound method BatchNormalization.call of <tensorflow.python.layers.normalization.BatchNormalization object at 0x7fc102226cf8>> could not be transformed and will be executed as-is. Please report this to the AutgoGraph team. When filing the bug, set the verbosity to 10 (on Linux, `export AUTOGRAPH_VERBOSITY=10`) and attach the full output. Cause: converting <bound method BatchNormalization.call of <tensorflow.python.layers.normalization.BatchNormalization object at 0x7fc102226cf8>>: AssertionError: Bad argument number for Name: 3, expecting 4
W0518 07:34:38.140160 140469935716096 ag_logging.py:145] Entity <bound method BatchNormalization.call of <tensorflow.python.layers.normalization.BatchNormalization object at 0x7fc102226cf8>> could not be transformed and will be executed as-is. Please report this to the AutgoGraph team. When filing the bug, set the verbosity to 10 (on Linux, `export AUTOGRAPH_VERBOSITY=10`) and attach the full output. Cause: converting <bound method BatchNormalization.call of <tensorflow.python.layers.normalization.BatchNormalization object at 0x7fc102226cf8>>: AssertionError: Bad argument number for Name: 3, expecting 4
WARNING:tensorflow:Entity <bound method Conv.call of <tensorflow.python.layers.convolutional.Conv2D object at 0x7fc1021f7978>> could not be transformed and will be executed as-is. Please report this to the AutgoGraph team. When filing the bug, set the verbosity to 10 (on Linux, `export AUTOGRAPH_VERBOSITY=10`) and attach the full output. Cause: converting <bound method Conv.call of <tensorflow.python.layers.convolutional.Conv2D object at 0x7fc1021f7978>>: AssertionError: Bad argument number for Name: 3, expecting 4
W0518 07:34:38.198870 140469935716096 ag_logging.py:145] Entity <bound method Conv.call of <tensorflow.python.layers.convolutional.Conv2D object at 0x7fc1021f7978>> could not be transformed and will be executed as-is. Please report this to the AutgoGraph team. When filing the bug, set the verbosity to 10 (on Linux, `export AUTOGRAPH_VERBOSITY=10`) and attach the full output. Cause: converting <bound method Conv.call of <tensorflow.python.layers.convolutional.Conv2D object at 0x7fc1021f7978>>: AssertionError: Bad argument number for Name: 3, expecting 4
WARNING:tensorflow:Entity <bound method BatchNormalization.call of <tensorflow.python.layers.normalization.BatchNormalization object at 0x7fc102226cf8>> could not be transformed and will be executed as-is. Please report this to the AutgoGraph team. When filing the bug, set the verbosity to 10 (on Linux, `export AUTOGRAPH_VERBOSITY=10`) and attach the full output. Cause: converting <bound method BatchNormalization.call of <tensorflow.python.layers.normalization.BatchNormalization object at 0x7fc102226cf8>>: AssertionError: Bad argument number for Name: 3, expecting 4
W0518 07:34:38.223821 140469935716096 ag_logging.py:145] Entity <bound method BatchNormalization.call of <tensorflow.python.layers.normalization.BatchNormalization object at 0x7fc102226cf8>> could not be transformed and will be executed as-is. Please report this to the AutgoGraph team. When filing the bug, set the verbosity to 10 (on Linux, `export AUTOGRAPH_VERBOSITY=10`) and attach the full output. Cause: converting <bound method BatchNormalization.call of <tensorflow.python.layers.normalization.BatchNormalization object at 0x7fc102226cf8>>: AssertionError: Bad argument number for Name: 3, expecting 4
WARNING:tensorflow:Entity <bound method Conv.call of <tensorflow.python.layers.convolutional.Conv2D object at 0x7fc10217b668>> could not be transformed and will be executed as-is. Please report this to the AutgoGraph team. When filing the bug, set the verbosity to 10 (on Linux, `export AUTOGRAPH_VERBOSITY=10`) and attach the full output. Cause: converting <bound method Conv.call of <tensorflow.python.layers.convolutional.Conv2D object at 0x7fc10217b668>>: AssertionError: Bad argument number for Name: 3, expecting 4
W0518 07:34:38.284304 140469935716096 ag_logging.py:145] Entity <bound method Conv.call of <tensorflow.python.layers.convolutional.Conv2D object at 0x7fc10217b668>> could not be transformed and will be executed as-is. Please report this to the AutgoGraph team. When filing the bug, set the verbosity to 10 (on Linux, `export AUTOGRAPH_VERBOSITY=10`) and attach the full output. Cause: converting <bound method Conv.call of <tensorflow.python.layers.convolutional.Conv2D object at 0x7fc10217b668>>: AssertionError: Bad argument number for Name: 3, expecting 4
WARNING:tensorflow:Entity <bound method BatchNormalization.call of <tensorflow.python.layers.normalization.BatchNormalization object at 0x7fc102226cf8>> could not be transformed and will be executed as-is. Please report this to the AutgoGraph team. When filing the bug, set the verbosity to 10 (on Linux, `export AUTOGRAPH_VERBOSITY=10`) and attach the full output. Cause: converting <bound method BatchNormalization.call of <tensorflow.python.layers.normalization.BatchNormalization object at 0x7fc102226cf8>>: AssertionError: Bad argument number for Name: 3, expecting 4
W0518 07:34:38.309896 140469935716096 ag_logging.py:145] Entity <bound method BatchNormalization.call of <tensorflow.python.layers.normalization.BatchNormalization object at 0x7fc102226cf8>> could not be transformed and will be executed as-is. Please report this to the AutgoGraph team. When filing the bug, set the verbosity to 10 (on Linux, `export AUTOGRAPH_VERBOSITY=10`) and attach the full output. Cause: converting <bound method BatchNormalization.call of <tensorflow.python.layers.normalization.BatchNormalization object at 0x7fc102226cf8>>: AssertionError: Bad argument number for Name: 3, expecting 4
WARNING:tensorflow:Entity <bound method Conv.call of <tensorflow.python.layers.convolutional.Conv2D object at 0x7fc1020e0a20>> could not be transformed and will be executed as-is. Please report this to the AutgoGraph team. When filing the bug, set the verbosity to 10 (on Linux, `export AUTOGRAPH_VERBOSITY=10`) and attach the full output. Cause: converting <bound method Conv.call of <tensorflow.python.layers.convolutional.Conv2D object at 0x7fc1020e0a20>>: AssertionError: Bad argument number for Name: 3, expecting 4
W0518 07:34:38.369722 140469935716096 ag_logging.py:145] Entity <bound method Conv.call of <tensorflow.python.layers.convolutional.Conv2D object at 0x7fc1020e0a20>> could not be transformed and will be executed as-is. Please report this to the AutgoGraph team. When filing the bug, set the verbosity to 10 (on Linux, `export AUTOGRAPH_VERBOSITY=10`) and attach the full output. Cause: converting <bound method Conv.call of <tensorflow.python.layers.convolutional.Conv2D object at 0x7fc1020e0a20>>: AssertionError: Bad argument number for Name: 3, expecting 4
WARNING:tensorflow:Entity <bound method BatchNormalization.call of <tensorflow.python.layers.normalization.BatchNormalization object at 0x7fc102226cf8>> could not be transformed and will be executed as-is. Please report this to the AutgoGraph team. When filing the bug, set the verbosity to 10 (on Linux, `export AUTOGRAPH_VERBOSITY=10`) and attach the full output. Cause: converting <bound method BatchNormalization.call of <tensorflow.python.layers.normalization.BatchNormalization object at 0x7fc102226cf8>>: AssertionError: Bad argument number for Name: 3, expecting 4
W0518 07:34:38.395138 140469935716096 ag_logging.py:145] Entity <bound method BatchNormalization.call of <tensorflow.python.layers.normalization.BatchNormalization object at 0x7fc102226cf8>> could not be transformed and will be executed as-is. Please report this to the AutgoGraph team. When filing the bug, set the verbosity to 10 (on Linux, `export AUTOGRAPH_VERBOSITY=10`) and attach the full output. Cause: converting <bound method BatchNormalization.call of <tensorflow.python.layers.normalization.BatchNormalization object at 0x7fc102226cf8>>: AssertionError: Bad argument number for Name: 3, expecting 4
WARNING:tensorflow:Entity <bound method Conv.call of <tensorflow.python.layers.convolutional.Conv2D object at 0x7fc101f9fe10>> could not be transformed and will be executed as-is. Please report this to the AutgoGraph team. When filing the bug, set the verbosity to 10 (on Linux, `export AUTOGRAPH_VERBOSITY=10`) and attach the full output. Cause: converting <bound method Conv.call of <tensorflow.python.layers.convolutional.Conv2D object at 0x7fc101f9fe10>>: AssertionError: Bad argument number for Name: 3, expecting 4
W0518 07:34:38.457705 140469935716096 ag_logging.py:145] Entity <bound method Conv.call of <tensorflow.python.layers.convolutional.Conv2D object at 0x7fc101f9fe10>> could not be transformed and will be executed as-is. Please report this to the AutgoGraph team. When filing the bug, set the verbosity to 10 (on Linux, `export AUTOGRAPH_VERBOSITY=10`) and attach the full output. Cause: converting <bound method Conv.call of <tensorflow.python.layers.convolutional.Conv2D object at 0x7fc101f9fe10>>: AssertionError: Bad argument number for Name: 3, expecting 4
WARNING:tensorflow:Entity <bound method BatchNormalization.call of <tensorflow.python.layers.normalization.BatchNormalization object at 0x7fc101fd1470>> could not be transformed and will be executed as-is. Please report this to the AutgoGraph team. When filing the bug, set the verbosity to 10 (on Linux, `export AUTOGRAPH_VERBOSITY=10`) and attach the full output. Cause: converting <bound method BatchNormalization.call of <tensorflow.python.layers.normalization.BatchNormalization object at 0x7fc101fd1470>>: AssertionError: Bad argument number for Name: 3, expecting 4
W0518 07:34:38.482498 140469935716096 ag_logging.py:145] Entity <bound method BatchNormalization.call of <tensorflow.python.layers.normalization.BatchNormalization object at 0x7fc101fd1470>> could not be transformed and will be executed as-is. Please report this to the AutgoGraph team. When filing the bug, set the verbosity to 10 (on Linux, `export AUTOGRAPH_VERBOSITY=10`) and attach the full output. Cause: converting <bound method BatchNormalization.call of <tensorflow.python.layers.normalization.BatchNormalization object at 0x7fc101fd1470>>: AssertionError: Bad argument number for Name: 3, expecting 4
WARNING:tensorflow:Entity <bound method Conv.call of <tensorflow.python.layers.convolutional.Conv2D object at 0x7fc101f9f2b0>> could not be transformed and will be executed as-is. Please report this to the AutgoGraph team. When filing the bug, set the verbosity to 10 (on Linux, `export AUTOGRAPH_VERBOSITY=10`) and attach the full output. Cause: converting <bound method Conv.call of <tensorflow.python.layers.convolutional.Conv2D object at 0x7fc101f9f2b0>>: AssertionError: Bad argument number for Name: 3, expecting 4
W0518 07:34:38.541954 140469935716096 ag_logging.py:145] Entity <bound method Conv.call of <tensorflow.python.layers.convolutional.Conv2D object at 0x7fc101f9f2b0>> could not be transformed and will be executed as-is. Please report this to the AutgoGraph team. When filing the bug, set the verbosity to 10 (on Linux, `export AUTOGRAPH_VERBOSITY=10`) and attach the full output. Cause: converting <bound method Conv.call of <tensorflow.python.layers.convolutional.Conv2D object at 0x7fc101f9f2b0>>: AssertionError: Bad argument number for Name: 3, expecting 4
WARNING:tensorflow:Entity <bound method BatchNormalization.call of <tensorflow.python.layers.normalization.BatchNormalization object at 0x7fc101f9f160>> could not be transformed and will be executed as-is. Please report this to the AutgoGraph team. When filing the bug, set the verbosity to 10 (on Linux, `export AUTOGRAPH_VERBOSITY=10`) and attach the full output. Cause: converting <bound method BatchNormalization.call of <tensorflow.python.layers.normalization.BatchNormalization object at 0x7fc101f9f160>>: AssertionError: Bad argument number for Name: 3, expecting 4
W0518 07:34:38.567317 140469935716096 ag_logging.py:145] Entity <bound method BatchNormalization.call of <tensorflow.python.layers.normalization.BatchNormalization object at 0x7fc101f9f160>> could not be transformed and will be executed as-is. Please report this to the AutgoGraph team. When filing the bug, set the verbosity to 10 (on Linux, `export AUTOGRAPH_VERBOSITY=10`) and attach the full output. Cause: converting <bound method BatchNormalization.call of <tensorflow.python.layers.normalization.BatchNormalization object at 0x7fc101f9f160>>: AssertionError: Bad argument number for Name: 3, expecting 4
WARNING:tensorflow:Entity <bound method Conv.call of <tensorflow.python.layers.convolutional.Conv2D object at 0x7fc101f9f2b0>> could not be transformed and will be executed as-is. Please report this to the AutgoGraph team. When filing the bug, set the verbosity to 10 (on Linux, `export AUTOGRAPH_VERBOSITY=10`) and attach the full output. Cause: converting <bound method Conv.call of <tensorflow.python.layers.convolutional.Conv2D object at 0x7fc101f9f2b0>>: AssertionError: Bad argument number for Name: 3, expecting 4
W0518 07:34:38.629128 140469935716096 ag_logging.py:145] Entity <bound method Conv.call of <tensorflow.python.layers.convolutional.Conv2D object at 0x7fc101f9f2b0>> could not be transformed and will be executed as-is. Please report this to the AutgoGraph team. When filing the bug, set the verbosity to 10 (on Linux, `export AUTOGRAPH_VERBOSITY=10`) and attach the full output. Cause: converting <bound method Conv.call of <tensorflow.python.layers.convolutional.Conv2D object at 0x7fc101f9f2b0>>: AssertionError: Bad argument number for Name: 3, expecting 4
WARNING:tensorflow:Entity <bound method BatchNormalization.call of <tensorflow.python.layers.normalization.BatchNormalization object at 0x7fc101f9f160>> could not be transformed and will be executed as-is. Please report this to the AutgoGraph team. When filing the bug, set the verbosity to 10 (on Linux, `export AUTOGRAPH_VERBOSITY=10`) and attach the full output. Cause: converting <bound method BatchNormalization.call of <tensorflow.python.layers.normalization.BatchNormalization object at 0x7fc101f9f160>>: AssertionError: Bad argument number for Name: 3, expecting 4
W0518 07:34:38.655007 140469935716096 ag_logging.py:145] Entity <bound method BatchNormalization.call of <tensorflow.python.layers.normalization.BatchNormalization object at 0x7fc101f9f160>> could not be transformed and will be executed as-is. Please report this to the AutgoGraph team. When filing the bug, set the verbosity to 10 (on Linux, `export AUTOGRAPH_VERBOSITY=10`) and attach the full output. Cause: converting <bound method BatchNormalization.call of <tensorflow.python.layers.normalization.BatchNormalization object at 0x7fc101f9f160>>: AssertionError: Bad argument number for Name: 3, expecting 4
WARNING:tensorflow:Entity <bound method Conv.call of <tensorflow.python.layers.convolutional.Conv2D object at 0x7fc101f9f2b0>> could not be transformed and will be executed as-is. Please report this to the AutgoGraph team. When filing the bug, set the verbosity to 10 (on Linux, `export AUTOGRAPH_VERBOSITY=10`) and attach the full output. Cause: converting <bound method Conv.call of <tensorflow.python.layers.convolutional.Conv2D object at 0x7fc101f9f2b0>>: AssertionError: Bad argument number for Name: 3, expecting 4
W0518 07:34:38.713901 140469935716096 ag_logging.py:145] Entity <bound method Conv.call of <tensorflow.python.layers.convolutional.Conv2D object at 0x7fc101f9f2b0>> could not be transformed and will be executed as-is. Please report this to the AutgoGraph team. When filing the bug, set the verbosity to 10 (on Linux, `export AUTOGRAPH_VERBOSITY=10`) and attach the full output. Cause: converting <bound method Conv.call of <tensorflow.python.layers.convolutional.Conv2D object at 0x7fc101f9f2b0>>: AssertionError: Bad argument number for Name: 3, expecting 4
WARNING:tensorflow:Entity <bound method BatchNormalization.call of <tensorflow.python.layers.normalization.BatchNormalization object at 0x7fc101f9f160>> could not be transformed and will be executed as-is. Please report this to the AutgoGraph team. When filing the bug, set the verbosity to 10 (on Linux, `export AUTOGRAPH_VERBOSITY=10`) and attach the full output. Cause: converting <bound method BatchNormalization.call of <tensorflow.python.layers.normalization.BatchNormalization object at 0x7fc101f9f160>>: AssertionError: Bad argument number for Name: 3, expecting 4
W0518 07:34:38.738579 140469935716096 ag_logging.py:145] Entity <bound method BatchNormalization.call of <tensorflow.python.layers.normalization.BatchNormalization object at 0x7fc101f9f160>> could not be transformed and will be executed as-is. Please report this to the AutgoGraph team. When filing the bug, set the verbosity to 10 (on Linux, `export AUTOGRAPH_VERBOSITY=10`) and attach the full output. Cause: converting <bound method BatchNormalization.call of <tensorflow.python.layers.normalization.BatchNormalization object at 0x7fc101f9f160>>: AssertionError: Bad argument number for Name: 3, expecting 4
WARNING:tensorflow:Entity <bound method Conv.call of <tensorflow.python.layers.convolutional.Conv2D object at 0x7fc101f9f2b0>> could not be transformed and will be executed as-is. Please report this to the AutgoGraph team. When filing the bug, set the verbosity to 10 (on Linux, `export AUTOGRAPH_VERBOSITY=10`) and attach the full output. Cause: converting <bound method Conv.call of <tensorflow.python.layers.convolutional.Conv2D object at 0x7fc101f9f2b0>>: AssertionError: Bad argument number for Name: 3, expecting 4
W0518 07:34:38.796750 140469935716096 ag_logging.py:145] Entity <bound method Conv.call of <tensorflow.python.layers.convolutional.Conv2D object at 0x7fc101f9f2b0>> could not be transformed and will be executed as-is. Please report this to the AutgoGraph team. When filing the bug, set the verbosity to 10 (on Linux, `export AUTOGRAPH_VERBOSITY=10`) and attach the full output. Cause: converting <bound method Conv.call of <tensorflow.python.layers.convolutional.Conv2D object at 0x7fc101f9f2b0>>: AssertionError: Bad argument number for Name: 3, expecting 4
WARNING:tensorflow:Entity <bound method BatchNormalization.call of <tensorflow.python.layers.normalization.BatchNormalization object at 0x7fc101f9f160>> could not be transformed and will be executed as-is. Please report this to the AutgoGraph team. When filing the bug, set the verbosity to 10 (on Linux, `export AUTOGRAPH_VERBOSITY=10`) and attach the full output. Cause: converting <bound method BatchNormalization.call of <tensorflow.python.layers.normalization.BatchNormalization object at 0x7fc101f9f160>>: AssertionError: Bad argument number for Name: 3, expecting 4
W0518 07:34:38.821553 140469935716096 ag_logging.py:145] Entity <bound method BatchNormalization.call of <tensorflow.python.layers.normalization.BatchNormalization object at 0x7fc101f9f160>> could not be transformed and will be executed as-is. Please report this to the AutgoGraph team. When filing the bug, set the verbosity to 10 (on Linux, `export AUTOGRAPH_VERBOSITY=10`) and attach the full output. Cause: converting <bound method BatchNormalization.call of <tensorflow.python.layers.normalization.BatchNormalization object at 0x7fc101f9f160>>: AssertionError: Bad argument number for Name: 3, expecting 4
WARNING:tensorflow:From /data2/MECo/tensorflow_models/models-1.11/official/resnet/resnet_model.py:546: dense (from tensorflow.python.layers.core) is deprecated and will be removed in a future version.
Instructions for updating:
Use keras.layers.dense instead.
W0518 07:34:38.826842 140469935716096 deprecation.py:323] From /data2/MECo/tensorflow_models/models-1.11/official/resnet/resnet_model.py:546: dense (from tensorflow.python.layers.core) is deprecated and will be removed in a future version.
Instructions for updating:
Use keras.layers.dense instead.
WARNING:tensorflow:From /home/jon/anaconda3/envs/tf1.14-gpu/lib/python3.6/site-packages/tensorflow/python/ops/init_ops.py:1251: calling VarianceScaling.__init__ (from tensorflow.python.ops.init_ops) with dtype is deprecated and will be removed in a future version.
Instructions for updating:
Call initializer instance with the dtype argument instead of passing it to the constructor
W0518 07:34:38.827926 140469935716096 deprecation.py:506] From /home/jon/anaconda3/envs/tf1.14-gpu/lib/python3.6/site-packages/tensorflow/python/ops/init_ops.py:1251: calling VarianceScaling.__init__ (from tensorflow.python.ops.init_ops) with dtype is deprecated and will be removed in a future version.
Instructions for updating:
Call initializer instance with the dtype argument instead of passing it to the constructor
WARNING:tensorflow:Entity <bound method Dense.call of <tensorflow.python.layers.core.Dense object at 0x7fc101ee01d0>> could not be transformed and will be executed as-is. Please report this to the AutgoGraph team. When filing the bug, set the verbosity to 10 (on Linux, `export AUTOGRAPH_VERBOSITY=10`) and attach the full output. Cause: converting <bound method Dense.call of <tensorflow.python.layers.core.Dense object at 0x7fc101ee01d0>>: AssertionError: Bad argument number for Name: 3, expecting 4
W0518 07:34:38.909329 140469935716096 ag_logging.py:145] Entity <bound method Dense.call of <tensorflow.python.layers.core.Dense object at 0x7fc101ee01d0>> could not be transformed and will be executed as-is. Please report this to the AutgoGraph team. When filing the bug, set the verbosity to 10 (on Linux, `export AUTOGRAPH_VERBOSITY=10`) and attach the full output. Cause: converting <bound method Dense.call of <tensorflow.python.layers.core.Dense object at 0x7fc101ee01d0>>: AssertionError: Bad argument number for Name: 3, expecting 4
WARNING:tensorflow:From /data2/MECo/tensorflow_models/models-1.11/official/resnet/resnet_run_loop.py:261: The name tf.losses.sparse_softmax_cross_entropy is deprecated. Please use tf.compat.v1.losses.sparse_softmax_cross_entropy instead.

W0518 07:34:38.912820 140469935716096 deprecation_wrapper.py:119] From /data2/MECo/tensorflow_models/models-1.11/official/resnet/resnet_run_loop.py:261: The name tf.losses.sparse_softmax_cross_entropy is deprecated. Please use tf.compat.v1.losses.sparse_softmax_cross_entropy instead.

WARNING:tensorflow:From /home/jon/anaconda3/envs/tf1.14-gpu/lib/python3.6/site-packages/tensorflow/python/ops/losses/losses_impl.py:121: add_dispatch_support.<locals>.wrapper (from tensorflow.python.ops.array_ops) is deprecated and will be removed in a future version.
Instructions for updating:
Use tf.where in 2.0, which has the same broadcast rule as np.where
W0518 07:34:38.921577 140469935716096 deprecation.py:323] From /home/jon/anaconda3/envs/tf1.14-gpu/lib/python3.6/site-packages/tensorflow/python/ops/losses/losses_impl.py:121: add_dispatch_support.<locals>.wrapper (from tensorflow.python.ops.array_ops) is deprecated and will be removed in a future version.
Instructions for updating:
Use tf.where in 2.0, which has the same broadcast rule as np.where
WARNING:tensorflow:From /data2/MECo/tensorflow_models/models-1.11/official/resnet/resnet_run_loop.py:266: The name tf.summary.scalar is deprecated. Please use tf.compat.v1.summary.scalar instead.

W0518 07:34:38.929864 140469935716096 deprecation_wrapper.py:119] From /data2/MECo/tensorflow_models/models-1.11/official/resnet/resnet_run_loop.py:266: The name tf.summary.scalar is deprecated. Please use tf.compat.v1.summary.scalar instead.

WARNING:tensorflow:From /data2/MECo/tensorflow_models/models-1.11/official/resnet/resnet_run_loop.py:333: The name tf.metrics.accuracy is deprecated. Please use tf.compat.v1.metrics.accuracy instead.

W0518 07:34:38.948466 140469935716096 deprecation_wrapper.py:119] From /data2/MECo/tensorflow_models/models-1.11/official/resnet/resnet_run_loop.py:333: The name tf.metrics.accuracy is deprecated. Please use tf.compat.v1.metrics.accuracy instead.

WARNING:tensorflow:From /data2/MECo/tensorflow_models/models-1.11/official/resnet/resnet_run_loop.py:334: The name tf.metrics.mean is deprecated. Please use tf.compat.v1.metrics.mean instead.

W0518 07:34:38.961470 140469935716096 deprecation_wrapper.py:119] From /data2/MECo/tensorflow_models/models-1.11/official/resnet/resnet_run_loop.py:334: The name tf.metrics.mean is deprecated. Please use tf.compat.v1.metrics.mean instead.

INFO:tensorflow:Done calling model_fn.
I0518 07:34:38.977762 140469935716096 estimator.py:1147] Done calling model_fn.
INFO:tensorflow:Starting evaluation at 2020-05-18T07:34:38Z
I0518 07:34:38.994241 140469935716096 evaluation.py:255] Starting evaluation at 2020-05-18T07:34:38Z
INFO:tensorflow:Graph was finalized.
I0518 07:34:39.338464 140469935716096 monitored_session.py:240] Graph was finalized.
2020-05-18 07:34:39.339587: I tensorflow/core/common_runtime/gpu/gpu_device.cc:1640] Found device 0 with properties: 
name: GeForce GTX 1080 Ti major: 6 minor: 1 memoryClockRate(GHz): 1.6705
pciBusID: 0000:02:00.0
2020-05-18 07:34:39.340288: I tensorflow/core/common_runtime/gpu/gpu_device.cc:1640] Found device 1 with properties: 
name: GeForce GTX 1080 Ti major: 6 minor: 1 memoryClockRate(GHz): 1.6705
pciBusID: 0000:03:00.0
2020-05-18 07:34:39.340318: I tensorflow/stream_executor/platform/default/dso_loader.cc:42] Successfully opened dynamic library libcudart.so.10.0
2020-05-18 07:34:39.340328: I tensorflow/stream_executor/platform/default/dso_loader.cc:42] Successfully opened dynamic library libcublas.so.10.0
2020-05-18 07:34:39.340335: I tensorflow/stream_executor/platform/default/dso_loader.cc:42] Successfully opened dynamic library libcufft.so.10.0
2020-05-18 07:34:39.340346: I tensorflow/stream_executor/platform/default/dso_loader.cc:42] Successfully opened dynamic library libcurand.so.10.0
2020-05-18 07:34:39.340370: I tensorflow/stream_executor/platform/default/dso_loader.cc:42] Successfully opened dynamic library libcusolver.so.10.0
2020-05-18 07:34:39.340397: I tensorflow/stream_executor/platform/default/dso_loader.cc:42] Successfully opened dynamic library libcusparse.so.10.0
2020-05-18 07:34:39.340412: I tensorflow/stream_executor/platform/default/dso_loader.cc:42] Successfully opened dynamic library libcudnn.so.7
2020-05-18 07:34:39.342714: I tensorflow/core/common_runtime/gpu/gpu_device.cc:1763] Adding visible gpu devices: 0, 1
2020-05-18 07:34:39.342766: I tensorflow/core/common_runtime/gpu/gpu_device.cc:1181] Device interconnect StreamExecutor with strength 1 edge matrix:
2020-05-18 07:34:39.342776: I tensorflow/core/common_runtime/gpu/gpu_device.cc:1187]      0 1 
2020-05-18 07:34:39.342797: I tensorflow/core/common_runtime/gpu/gpu_device.cc:1200] 0:   N Y 
2020-05-18 07:34:39.342803: I tensorflow/core/common_runtime/gpu/gpu_device.cc:1200] 1:   Y N 
2020-05-18 07:34:39.344573: I tensorflow/core/common_runtime/gpu/gpu_device.cc:1326] Created TensorFlow device (/job:localhost/replica:0/task:0/device:GPU:0 with 10083 MB memory) -> physical GPU (device: 0, name: GeForce GTX 1080 Ti, pci bus id: 0000:02:00.0, compute capability: 6.1)
2020-05-18 07:34:39.345251: I tensorflow/core/common_runtime/gpu/gpu_device.cc:1326] Created TensorFlow device (/job:localhost/replica:0/task:0/device:GPU:1 with 10479 MB memory) -> physical GPU (device: 1, name: GeForce GTX 1080 Ti, pci bus id: 0000:03:00.0, compute capability: 6.1)
WARNING:tensorflow:From /home/jon/anaconda3/envs/tf1.14-gpu/lib/python3.6/site-packages/tensorflow/python/training/saver.py:1276: checkpoint_exists (from tensorflow.python.training.checkpoint_management) is deprecated and will be removed in a future version.
Instructions for updating:
Use standard file APIs to check for files with this prefix.
W0518 07:34:39.346719 140469935716096 deprecation.py:323] From /home/jon/anaconda3/envs/tf1.14-gpu/lib/python3.6/site-packages/tensorflow/python/training/saver.py:1276: checkpoint_exists (from tensorflow.python.training.checkpoint_management) is deprecated and will be removed in a future version.
Instructions for updating:
Use standard file APIs to check for files with this prefix.
INFO:tensorflow:Restoring parameters from ./resnet_21/model.ckpt-4802119
I0518 07:34:39.348749 140469935716096 saver.py:1280] Restoring parameters from ./resnet_21/model.ckpt-4802119
2020-05-18 07:34:41.409215: W tensorflow/compiler/jit/mark_for_compilation_pass.cc:1412] (One-time warning): Not using XLA:CPU for cluster because envvar TF_XLA_FLAGS=--tf_xla_cpu_global_jit was not set.  If you want XLA:CPU, either set that envvar, or use experimental_jit_scope to enable XLA:CPU.  To confirm that XLA is active, pass --vmodule=xla_compilation_cache=1 (as a proper command-line flag, not via TF_XLA_FLAGS) or set the envvar XLA_FLAGS=--xla_hlo_profile.
INFO:tensorflow:Running local_init_op.
I0518 07:34:41.426783 140469935716096 session_manager.py:500] Running local_init_op.
INFO:tensorflow:Done running local_init_op.
I0518 07:34:41.452072 140469935716096 session_manager.py:502] Done running local_init_op.
2020-05-18 07:34:41.889910: I tensorflow/stream_executor/platform/default/dso_loader.cc:42] Successfully opened dynamic library libcublas.so.10.0
2020-05-18 07:34:42.374495: I tensorflow/stream_executor/platform/default/dso_loader.cc:42] Successfully opened dynamic library libcudnn.so.7
INFO:tensorflow:Finished evaluation at 2020-05-18-07:35:23
I0518 07:35:23.288594 140469935716096 evaluation.py:275] Finished evaluation at 2020-05-18-07:35:23
INFO:tensorflow:Saving dict for global step 4802119: accuracy = 0.65514, accuracy_top_5 = 0.87524, global_step = 4802119, loss = 1.6189368
I0518 07:35:23.288824 140469935716096 estimator.py:2039] Saving dict for global step 4802119: accuracy = 0.65514, accuracy_top_5 = 0.87524, global_step = 4802119, loss = 1.6189368
INFO:tensorflow:Saving 'checkpoint_path' summary for global step 4802119: ./resnet_21/model.ckpt-4802119
I0518 07:35:23.455015 140469935716096 estimator.py:2099] Saving 'checkpoint_path' summary for global step 4802119: ./resnet_21/model.ckpt-4802119
INFO:tensorflow:Benchmark metric: {'name': 'accuracy', 'value': 0.6551399827003479, 'unit': None, 'global_step': 4802119, 'timestamp': '2020-05-18T11:35:23.455475Z', 'extras': []}
I0518 07:35:23.455514 140469935716096 logger.py:146] Benchmark metric: {'name': 'accuracy', 'value': 0.6551399827003479, 'unit': None, 'global_step': 4802119, 'timestamp': '2020-05-18T11:35:23.455475Z', 'extras': []}
INFO:tensorflow:Benchmark metric: {'name': 'accuracy_top_5', 'value': 0.8752400279045105, 'unit': None, 'global_step': 4802119, 'timestamp': '2020-05-18T11:35:23.455653Z', 'extras': []}
I0518 07:35:23.455681 140469935716096 logger.py:146] Benchmark metric: {'name': 'accuracy_top_5', 'value': 0.8752400279045105, 'unit': None, 'global_step': 4802119, 'timestamp': '2020-05-18T11:35:23.455653Z', 'extras': []}
INFO:tensorflow:Benchmark metric: {'name': 'loss', 'value': 1.6189367771148682, 'unit': None, 'global_step': 4802119, 'timestamp': '2020-05-18T11:35:23.455779Z', 'extras': []}
I0518 07:35:23.455800 140469935716096 logger.py:146] Benchmark metric: {'name': 'loss', 'value': 1.6189367771148682, 'unit': None, 'global_step': 4802119, 'timestamp': '2020-05-18T11:35:23.455779Z', 'extras': []}
WARNING:tensorflow:From /data2/MECo/tensorflow_models/models-1.11/official/resnet/resnet_run_loop.py:492: Estimator.export_savedmodel (from tensorflow_estimator.python.estimator.estimator) is deprecated and will be removed in a future version.
Instructions for updating:
This function has been renamed, use `export_saved_model` instead.
W0518 07:35:23.455936 140469935716096 deprecation.py:323] From /data2/MECo/tensorflow_models/models-1.11/official/resnet/resnet_run_loop.py:492: Estimator.export_savedmodel (from tensorflow_estimator.python.estimator.estimator) is deprecated and will be removed in a future version.
Instructions for updating:
This function has been renamed, use `export_saved_model` instead.
INFO:tensorflow:Calling model_fn.
I0518 07:35:23.462208 140469935716096 estimator.py:1145] Calling model_fn.
WARNING:tensorflow:Entity <bound method Conv.call of <tensorflow.python.layers.convolutional.Conv2D object at 0x7fc100dfc6d8>> could not be transformed and will be executed as-is. Please report this to the AutgoGraph team. When filing the bug, set the verbosity to 10 (on Linux, `export AUTOGRAPH_VERBOSITY=10`) and attach the full output. Cause: converting <bound method Conv.call of <tensorflow.python.layers.convolutional.Conv2D object at 0x7fc100dfc6d8>>: AssertionError: Bad argument number for Name: 3, expecting 4
W0518 07:35:23.526765 140469935716096 ag_logging.py:145] Entity <bound method Conv.call of <tensorflow.python.layers.convolutional.Conv2D object at 0x7fc100dfc6d8>> could not be transformed and will be executed as-is. Please report this to the AutgoGraph team. When filing the bug, set the verbosity to 10 (on Linux, `export AUTOGRAPH_VERBOSITY=10`) and attach the full output. Cause: converting <bound method Conv.call of <tensorflow.python.layers.convolutional.Conv2D object at 0x7fc100dfc6d8>>: AssertionError: Bad argument number for Name: 3, expecting 4
WARNING:tensorflow:Entity <bound method BatchNormalization.call of <tensorflow.python.layers.normalization.BatchNormalization object at 0x7fc100e66898>> could not be transformed and will be executed as-is. Please report this to the AutgoGraph team. When filing the bug, set the verbosity to 10 (on Linux, `export AUTOGRAPH_VERBOSITY=10`) and attach the full output. Cause: converting <bound method BatchNormalization.call of <tensorflow.python.layers.normalization.BatchNormalization object at 0x7fc100e66898>>: AssertionError: Bad argument number for Name: 3, expecting 4
W0518 07:35:23.553582 140469935716096 ag_logging.py:145] Entity <bound method BatchNormalization.call of <tensorflow.python.layers.normalization.BatchNormalization object at 0x7fc100e66898>> could not be transformed and will be executed as-is. Please report this to the AutgoGraph team. When filing the bug, set the verbosity to 10 (on Linux, `export AUTOGRAPH_VERBOSITY=10`) and attach the full output. Cause: converting <bound method BatchNormalization.call of <tensorflow.python.layers.normalization.BatchNormalization object at 0x7fc100e66898>>: AssertionError: Bad argument number for Name: 3, expecting 4
WARNING:tensorflow:Entity <bound method Pooling2D.call of <tensorflow.python.layers.pooling.MaxPooling2D object at 0x7fc100e66898>> could not be transformed and will be executed as-is. Please report this to the AutgoGraph team. When filing the bug, set the verbosity to 10 (on Linux, `export AUTOGRAPH_VERBOSITY=10`) and attach the full output. Cause: converting <bound method Pooling2D.call of <tensorflow.python.layers.pooling.MaxPooling2D object at 0x7fc100e66898>>: AssertionError: Bad argument number for Name: 3, expecting 4
W0518 07:35:23.595824 140469935716096 ag_logging.py:145] Entity <bound method Pooling2D.call of <tensorflow.python.layers.pooling.MaxPooling2D object at 0x7fc100e66898>> could not be transformed and will be executed as-is. Please report this to the AutgoGraph team. When filing the bug, set the verbosity to 10 (on Linux, `export AUTOGRAPH_VERBOSITY=10`) and attach the full output. Cause: converting <bound method Pooling2D.call of <tensorflow.python.layers.pooling.MaxPooling2D object at 0x7fc100e66898>>: AssertionError: Bad argument number for Name: 3, expecting 4
WARNING:tensorflow:Entity <bound method Conv.call of <tensorflow.python.layers.convolutional.Conv2D object at 0x7fc100dfc940>> could not be transformed and will be executed as-is. Please report this to the AutgoGraph team. When filing the bug, set the verbosity to 10 (on Linux, `export AUTOGRAPH_VERBOSITY=10`) and attach the full output. Cause: converting <bound method Conv.call of <tensorflow.python.layers.convolutional.Conv2D object at 0x7fc100dfc940>>: AssertionError: Bad argument number for Name: 3, expecting 4
W0518 07:35:23.655073 140469935716096 ag_logging.py:145] Entity <bound method Conv.call of <tensorflow.python.layers.convolutional.Conv2D object at 0x7fc100dfc940>> could not be transformed and will be executed as-is. Please report this to the AutgoGraph team. When filing the bug, set the verbosity to 10 (on Linux, `export AUTOGRAPH_VERBOSITY=10`) and attach the full output. Cause: converting <bound method Conv.call of <tensorflow.python.layers.convolutional.Conv2D object at 0x7fc100dfc940>>: AssertionError: Bad argument number for Name: 3, expecting 4
WARNING:tensorflow:Entity <bound method BatchNormalization.call of <tensorflow.python.layers.normalization.BatchNormalization object at 0x7fc101fd1b38>> could not be transformed and will be executed as-is. Please report this to the AutgoGraph team. When filing the bug, set the verbosity to 10 (on Linux, `export AUTOGRAPH_VERBOSITY=10`) and attach the full output. Cause: converting <bound method BatchNormalization.call of <tensorflow.python.layers.normalization.BatchNormalization object at 0x7fc101fd1b38>>: AssertionError: Bad argument number for Name: 3, expecting 4
W0518 07:35:23.680437 140469935716096 ag_logging.py:145] Entity <bound method BatchNormalization.call of <tensorflow.python.layers.normalization.BatchNormalization object at 0x7fc101fd1b38>> could not be transformed and will be executed as-is. Please report this to the AutgoGraph team. When filing the bug, set the verbosity to 10 (on Linux, `export AUTOGRAPH_VERBOSITY=10`) and attach the full output. Cause: converting <bound method BatchNormalization.call of <tensorflow.python.layers.normalization.BatchNormalization object at 0x7fc101fd1b38>>: AssertionError: Bad argument number for Name: 3, expecting 4
WARNING:tensorflow:Entity <bound method Conv.call of <tensorflow.python.layers.convolutional.Conv2D object at 0x7fc102452be0>> could not be transformed and will be executed as-is. Please report this to the AutgoGraph team. When filing the bug, set the verbosity to 10 (on Linux, `export AUTOGRAPH_VERBOSITY=10`) and attach the full output. Cause: converting <bound method Conv.call of <tensorflow.python.layers.convolutional.Conv2D object at 0x7fc102452be0>>: AssertionError: Bad argument number for Name: 3, expecting 4
W0518 07:35:23.739904 140469935716096 ag_logging.py:145] Entity <bound method Conv.call of <tensorflow.python.layers.convolutional.Conv2D object at 0x7fc102452be0>> could not be transformed and will be executed as-is. Please report this to the AutgoGraph team. When filing the bug, set the verbosity to 10 (on Linux, `export AUTOGRAPH_VERBOSITY=10`) and attach the full output. Cause: converting <bound method Conv.call of <tensorflow.python.layers.convolutional.Conv2D object at 0x7fc102452be0>>: AssertionError: Bad argument number for Name: 3, expecting 4
WARNING:tensorflow:Entity <bound method BatchNormalization.call of <tensorflow.python.layers.normalization.BatchNormalization object at 0x7fc101e30a58>> could not be transformed and will be executed as-is. Please report this to the AutgoGraph team. When filing the bug, set the verbosity to 10 (on Linux, `export AUTOGRAPH_VERBOSITY=10`) and attach the full output. Cause: converting <bound method BatchNormalization.call of <tensorflow.python.layers.normalization.BatchNormalization object at 0x7fc101e30a58>>: AssertionError: Bad argument number for Name: 3, expecting 4
W0518 07:35:23.764980 140469935716096 ag_logging.py:145] Entity <bound method BatchNormalization.call of <tensorflow.python.layers.normalization.BatchNormalization object at 0x7fc101e30a58>> could not be transformed and will be executed as-is. Please report this to the AutgoGraph team. When filing the bug, set the verbosity to 10 (on Linux, `export AUTOGRAPH_VERBOSITY=10`) and attach the full output. Cause: converting <bound method BatchNormalization.call of <tensorflow.python.layers.normalization.BatchNormalization object at 0x7fc101e30a58>>: AssertionError: Bad argument number for Name: 3, expecting 4
WARNING:tensorflow:Entity <bound method Conv.call of <tensorflow.python.layers.convolutional.Conv2D object at 0x7fc101ec8400>> could not be transformed and will be executed as-is. Please report this to the AutgoGraph team. When filing the bug, set the verbosity to 10 (on Linux, `export AUTOGRAPH_VERBOSITY=10`) and attach the full output. Cause: converting <bound method Conv.call of <tensorflow.python.layers.convolutional.Conv2D object at 0x7fc101ec8400>>: AssertionError: Bad argument number for Name: 3, expecting 4
W0518 07:35:23.824279 140469935716096 ag_logging.py:145] Entity <bound method Conv.call of <tensorflow.python.layers.convolutional.Conv2D object at 0x7fc101ec8400>> could not be transformed and will be executed as-is. Please report this to the AutgoGraph team. When filing the bug, set the verbosity to 10 (on Linux, `export AUTOGRAPH_VERBOSITY=10`) and attach the full output. Cause: converting <bound method Conv.call of <tensorflow.python.layers.convolutional.Conv2D object at 0x7fc101ec8400>>: AssertionError: Bad argument number for Name: 3, expecting 4
WARNING:tensorflow:Entity <bound method BatchNormalization.call of <tensorflow.python.layers.normalization.BatchNormalization object at 0x7fc101e30a58>> could not be transformed and will be executed as-is. Please report this to the AutgoGraph team. When filing the bug, set the verbosity to 10 (on Linux, `export AUTOGRAPH_VERBOSITY=10`) and attach the full output. Cause: converting <bound method BatchNormalization.call of <tensorflow.python.layers.normalization.BatchNormalization object at 0x7fc101e30a58>>: AssertionError: Bad argument number for Name: 3, expecting 4
W0518 07:35:23.849683 140469935716096 ag_logging.py:145] Entity <bound method BatchNormalization.call of <tensorflow.python.layers.normalization.BatchNormalization object at 0x7fc101e30a58>> could not be transformed and will be executed as-is. Please report this to the AutgoGraph team. When filing the bug, set the verbosity to 10 (on Linux, `export AUTOGRAPH_VERBOSITY=10`) and attach the full output. Cause: converting <bound method BatchNormalization.call of <tensorflow.python.layers.normalization.BatchNormalization object at 0x7fc101e30a58>>: AssertionError: Bad argument number for Name: 3, expecting 4
WARNING:tensorflow:Entity <bound method Conv.call of <tensorflow.python.layers.convolutional.Conv2D object at 0x7fc102452be0>> could not be transformed and will be executed as-is. Please report this to the AutgoGraph team. When filing the bug, set the verbosity to 10 (on Linux, `export AUTOGRAPH_VERBOSITY=10`) and attach the full output. Cause: converting <bound method Conv.call of <tensorflow.python.layers.convolutional.Conv2D object at 0x7fc102452be0>>: AssertionError: Bad argument number for Name: 3, expecting 4
W0518 07:35:23.909960 140469935716096 ag_logging.py:145] Entity <bound method Conv.call of <tensorflow.python.layers.convolutional.Conv2D object at 0x7fc102452be0>> could not be transformed and will be executed as-is. Please report this to the AutgoGraph team. When filing the bug, set the verbosity to 10 (on Linux, `export AUTOGRAPH_VERBOSITY=10`) and attach the full output. Cause: converting <bound method Conv.call of <tensorflow.python.layers.convolutional.Conv2D object at 0x7fc102452be0>>: AssertionError: Bad argument number for Name: 3, expecting 4
WARNING:tensorflow:Entity <bound method BatchNormalization.call of <tensorflow.python.layers.normalization.BatchNormalization object at 0x7fc102452be0>> could not be transformed and will be executed as-is. Please report this to the AutgoGraph team. When filing the bug, set the verbosity to 10 (on Linux, `export AUTOGRAPH_VERBOSITY=10`) and attach the full output. Cause: converting <bound method BatchNormalization.call of <tensorflow.python.layers.normalization.BatchNormalization object at 0x7fc102452be0>>: AssertionError: Bad argument number for Name: 3, expecting 4
W0518 07:35:23.935214 140469935716096 ag_logging.py:145] Entity <bound method BatchNormalization.call of <tensorflow.python.layers.normalization.BatchNormalization object at 0x7fc102452be0>> could not be transformed and will be executed as-is. Please report this to the AutgoGraph team. When filing the bug, set the verbosity to 10 (on Linux, `export AUTOGRAPH_VERBOSITY=10`) and attach the full output. Cause: converting <bound method BatchNormalization.call of <tensorflow.python.layers.normalization.BatchNormalization object at 0x7fc102452be0>>: AssertionError: Bad argument number for Name: 3, expecting 4
WARNING:tensorflow:Entity <bound method Conv.call of <tensorflow.python.layers.convolutional.Conv2D object at 0x7fc0941c72b0>> could not be transformed and will be executed as-is. Please report this to the AutgoGraph team. When filing the bug, set the verbosity to 10 (on Linux, `export AUTOGRAPH_VERBOSITY=10`) and attach the full output. Cause: converting <bound method Conv.call of <tensorflow.python.layers.convolutional.Conv2D object at 0x7fc0941c72b0>>: AssertionError: Bad argument number for Name: 3, expecting 4
W0518 07:35:23.994940 140469935716096 ag_logging.py:145] Entity <bound method Conv.call of <tensorflow.python.layers.convolutional.Conv2D object at 0x7fc0941c72b0>> could not be transformed and will be executed as-is. Please report this to the AutgoGraph team. When filing the bug, set the verbosity to 10 (on Linux, `export AUTOGRAPH_VERBOSITY=10`) and attach the full output. Cause: converting <bound method Conv.call of <tensorflow.python.layers.convolutional.Conv2D object at 0x7fc0941c72b0>>: AssertionError: Bad argument number for Name: 3, expecting 4
WARNING:tensorflow:Entity <bound method BatchNormalization.call of <tensorflow.python.layers.normalization.BatchNormalization object at 0x7fc102452be0>> could not be transformed and will be executed as-is. Please report this to the AutgoGraph team. When filing the bug, set the verbosity to 10 (on Linux, `export AUTOGRAPH_VERBOSITY=10`) and attach the full output. Cause: converting <bound method BatchNormalization.call of <tensorflow.python.layers.normalization.BatchNormalization object at 0x7fc102452be0>>: AssertionError: Bad argument number for Name: 3, expecting 4
W0518 07:35:24.020027 140469935716096 ag_logging.py:145] Entity <bound method BatchNormalization.call of <tensorflow.python.layers.normalization.BatchNormalization object at 0x7fc102452be0>> could not be transformed and will be executed as-is. Please report this to the AutgoGraph team. When filing the bug, set the verbosity to 10 (on Linux, `export AUTOGRAPH_VERBOSITY=10`) and attach the full output. Cause: converting <bound method BatchNormalization.call of <tensorflow.python.layers.normalization.BatchNormalization object at 0x7fc102452be0>>: AssertionError: Bad argument number for Name: 3, expecting 4
WARNING:tensorflow:Entity <bound method Conv.call of <tensorflow.python.layers.convolutional.Conv2D object at 0x7fc094052048>> could not be transformed and will be executed as-is. Please report this to the AutgoGraph team. When filing the bug, set the verbosity to 10 (on Linux, `export AUTOGRAPH_VERBOSITY=10`) and attach the full output. Cause: converting <bound method Conv.call of <tensorflow.python.layers.convolutional.Conv2D object at 0x7fc094052048>>: AssertionError: Bad argument number for Name: 3, expecting 4
W0518 07:35:24.081523 140469935716096 ag_logging.py:145] Entity <bound method Conv.call of <tensorflow.python.layers.convolutional.Conv2D object at 0x7fc094052048>> could not be transformed and will be executed as-is. Please report this to the AutgoGraph team. When filing the bug, set the verbosity to 10 (on Linux, `export AUTOGRAPH_VERBOSITY=10`) and attach the full output. Cause: converting <bound method Conv.call of <tensorflow.python.layers.convolutional.Conv2D object at 0x7fc094052048>>: AssertionError: Bad argument number for Name: 3, expecting 4
WARNING:tensorflow:Entity <bound method BatchNormalization.call of <tensorflow.python.layers.normalization.BatchNormalization object at 0x7fc0941bc940>> could not be transformed and will be executed as-is. Please report this to the AutgoGraph team. When filing the bug, set the verbosity to 10 (on Linux, `export AUTOGRAPH_VERBOSITY=10`) and attach the full output. Cause: converting <bound method BatchNormalization.call of <tensorflow.python.layers.normalization.BatchNormalization object at 0x7fc0941bc940>>: AssertionError: Bad argument number for Name: 3, expecting 4
W0518 07:35:24.107993 140469935716096 ag_logging.py:145] Entity <bound method BatchNormalization.call of <tensorflow.python.layers.normalization.BatchNormalization object at 0x7fc0941bc940>> could not be transformed and will be executed as-is. Please report this to the AutgoGraph team. When filing the bug, set the verbosity to 10 (on Linux, `export AUTOGRAPH_VERBOSITY=10`) and attach the full output. Cause: converting <bound method BatchNormalization.call of <tensorflow.python.layers.normalization.BatchNormalization object at 0x7fc0941bc940>>: AssertionError: Bad argument number for Name: 3, expecting 4
WARNING:tensorflow:Entity <bound method Conv.call of <tensorflow.python.layers.convolutional.Conv2D object at 0x7fc094052860>> could not be transformed and will be executed as-is. Please report this to the AutgoGraph team. When filing the bug, set the verbosity to 10 (on Linux, `export AUTOGRAPH_VERBOSITY=10`) and attach the full output. Cause: converting <bound method Conv.call of <tensorflow.python.layers.convolutional.Conv2D object at 0x7fc094052860>>: AssertionError: Bad argument number for Name: 3, expecting 4
W0518 07:35:24.171442 140469935716096 ag_logging.py:145] Entity <bound method Conv.call of <tensorflow.python.layers.convolutional.Conv2D object at 0x7fc094052860>> could not be transformed and will be executed as-is. Please report this to the AutgoGraph team. When filing the bug, set the verbosity to 10 (on Linux, `export AUTOGRAPH_VERBOSITY=10`) and attach the full output. Cause: converting <bound method Conv.call of <tensorflow.python.layers.convolutional.Conv2D object at 0x7fc094052860>>: AssertionError: Bad argument number for Name: 3, expecting 4
WARNING:tensorflow:Entity <bound method BatchNormalization.call of <tensorflow.python.layers.normalization.BatchNormalization object at 0x7fc094052a90>> could not be transformed and will be executed as-is. Please report this to the AutgoGraph team. When filing the bug, set the verbosity to 10 (on Linux, `export AUTOGRAPH_VERBOSITY=10`) and attach the full output. Cause: converting <bound method BatchNormalization.call of <tensorflow.python.layers.normalization.BatchNormalization object at 0x7fc094052a90>>: AssertionError: Bad argument number for Name: 3, expecting 4
W0518 07:35:24.196648 140469935716096 ag_logging.py:145] Entity <bound method BatchNormalization.call of <tensorflow.python.layers.normalization.BatchNormalization object at 0x7fc094052a90>> could not be transformed and will be executed as-is. Please report this to the AutgoGraph team. When filing the bug, set the verbosity to 10 (on Linux, `export AUTOGRAPH_VERBOSITY=10`) and attach the full output. Cause: converting <bound method BatchNormalization.call of <tensorflow.python.layers.normalization.BatchNormalization object at 0x7fc094052a90>>: AssertionError: Bad argument number for Name: 3, expecting 4
WARNING:tensorflow:Entity <bound method Conv.call of <tensorflow.python.layers.convolutional.Conv2D object at 0x7fc0700190f0>> could not be transformed and will be executed as-is. Please report this to the AutgoGraph team. When filing the bug, set the verbosity to 10 (on Linux, `export AUTOGRAPH_VERBOSITY=10`) and attach the full output. Cause: converting <bound method Conv.call of <tensorflow.python.layers.convolutional.Conv2D object at 0x7fc0700190f0>>: AssertionError: Bad argument number for Name: 3, expecting 4
W0518 07:35:24.257042 140469935716096 ag_logging.py:145] Entity <bound method Conv.call of <tensorflow.python.layers.convolutional.Conv2D object at 0x7fc0700190f0>> could not be transformed and will be executed as-is. Please report this to the AutgoGraph team. When filing the bug, set the verbosity to 10 (on Linux, `export AUTOGRAPH_VERBOSITY=10`) and attach the full output. Cause: converting <bound method Conv.call of <tensorflow.python.layers.convolutional.Conv2D object at 0x7fc0700190f0>>: AssertionError: Bad argument number for Name: 3, expecting 4
WARNING:tensorflow:Entity <bound method BatchNormalization.call of <tensorflow.python.layers.normalization.BatchNormalization object at 0x7fc100e1c908>> could not be transformed and will be executed as-is. Please report this to the AutgoGraph team. When filing the bug, set the verbosity to 10 (on Linux, `export AUTOGRAPH_VERBOSITY=10`) and attach the full output. Cause: converting <bound method BatchNormalization.call of <tensorflow.python.layers.normalization.BatchNormalization object at 0x7fc100e1c908>>: AssertionError: Bad argument number for Name: 3, expecting 4
W0518 07:35:24.282676 140469935716096 ag_logging.py:145] Entity <bound method BatchNormalization.call of <tensorflow.python.layers.normalization.BatchNormalization object at 0x7fc100e1c908>> could not be transformed and will be executed as-is. Please report this to the AutgoGraph team. When filing the bug, set the verbosity to 10 (on Linux, `export AUTOGRAPH_VERBOSITY=10`) and attach the full output. Cause: converting <bound method BatchNormalization.call of <tensorflow.python.layers.normalization.BatchNormalization object at 0x7fc100e1c908>>: AssertionError: Bad argument number for Name: 3, expecting 4
WARNING:tensorflow:Entity <bound method Conv.call of <tensorflow.python.layers.convolutional.Conv2D object at 0x7fc0940e5860>> could not be transformed and will be executed as-is. Please report this to the AutgoGraph team. When filing the bug, set the verbosity to 10 (on Linux, `export AUTOGRAPH_VERBOSITY=10`) and attach the full output. Cause: converting <bound method Conv.call of <tensorflow.python.layers.convolutional.Conv2D object at 0x7fc0940e5860>>: AssertionError: Bad argument number for Name: 3, expecting 4
W0518 07:35:24.343596 140469935716096 ag_logging.py:145] Entity <bound method Conv.call of <tensorflow.python.layers.convolutional.Conv2D object at 0x7fc0940e5860>> could not be transformed and will be executed as-is. Please report this to the AutgoGraph team. When filing the bug, set the verbosity to 10 (on Linux, `export AUTOGRAPH_VERBOSITY=10`) and attach the full output. Cause: converting <bound method Conv.call of <tensorflow.python.layers.convolutional.Conv2D object at 0x7fc0940e5860>>: AssertionError: Bad argument number for Name: 3, expecting 4
WARNING:tensorflow:Entity <bound method BatchNormalization.call of <tensorflow.python.layers.normalization.BatchNormalization object at 0x7fc100e1c908>> could not be transformed and will be executed as-is. Please report this to the AutgoGraph team. When filing the bug, set the verbosity to 10 (on Linux, `export AUTOGRAPH_VERBOSITY=10`) and attach the full output. Cause: converting <bound method BatchNormalization.call of <tensorflow.python.layers.normalization.BatchNormalization object at 0x7fc100e1c908>>: AssertionError: Bad argument number for Name: 3, expecting 4
W0518 07:35:24.369392 140469935716096 ag_logging.py:145] Entity <bound method BatchNormalization.call of <tensorflow.python.layers.normalization.BatchNormalization object at 0x7fc100e1c908>> could not be transformed and will be executed as-is. Please report this to the AutgoGraph team. When filing the bug, set the verbosity to 10 (on Linux, `export AUTOGRAPH_VERBOSITY=10`) and attach the full output. Cause: converting <bound method BatchNormalization.call of <tensorflow.python.layers.normalization.BatchNormalization object at 0x7fc100e1c908>>: AssertionError: Bad argument number for Name: 3, expecting 4
WARNING:tensorflow:Entity <bound method Conv.call of <tensorflow.python.layers.convolutional.Conv2D object at 0x7fc040025b70>> could not be transformed and will be executed as-is. Please report this to the AutgoGraph team. When filing the bug, set the verbosity to 10 (on Linux, `export AUTOGRAPH_VERBOSITY=10`) and attach the full output. Cause: converting <bound method Conv.call of <tensorflow.python.layers.convolutional.Conv2D object at 0x7fc040025b70>>: AssertionError: Bad argument number for Name: 3, expecting 4
W0518 07:35:24.429672 140469935716096 ag_logging.py:145] Entity <bound method Conv.call of <tensorflow.python.layers.convolutional.Conv2D object at 0x7fc040025b70>> could not be transformed and will be executed as-is. Please report this to the AutgoGraph team. When filing the bug, set the verbosity to 10 (on Linux, `export AUTOGRAPH_VERBOSITY=10`) and attach the full output. Cause: converting <bound method Conv.call of <tensorflow.python.layers.convolutional.Conv2D object at 0x7fc040025b70>>: AssertionError: Bad argument number for Name: 3, expecting 4
WARNING:tensorflow:Entity <bound method BatchNormalization.call of <tensorflow.python.layers.normalization.BatchNormalization object at 0x7fc100e1c908>> could not be transformed and will be executed as-is. Please report this to the AutgoGraph team. When filing the bug, set the verbosity to 10 (on Linux, `export AUTOGRAPH_VERBOSITY=10`) and attach the full output. Cause: converting <bound method BatchNormalization.call of <tensorflow.python.layers.normalization.BatchNormalization object at 0x7fc100e1c908>>: AssertionError: Bad argument number for Name: 3, expecting 4
W0518 07:35:24.455752 140469935716096 ag_logging.py:145] Entity <bound method BatchNormalization.call of <tensorflow.python.layers.normalization.BatchNormalization object at 0x7fc100e1c908>> could not be transformed and will be executed as-is. Please report this to the AutgoGraph team. When filing the bug, set the verbosity to 10 (on Linux, `export AUTOGRAPH_VERBOSITY=10`) and attach the full output. Cause: converting <bound method BatchNormalization.call of <tensorflow.python.layers.normalization.BatchNormalization object at 0x7fc100e1c908>>: AssertionError: Bad argument number for Name: 3, expecting 4
WARNING:tensorflow:Entity <bound method Conv.call of <tensorflow.python.layers.convolutional.Conv2D object at 0x7fc0941bcf60>> could not be transformed and will be executed as-is. Please report this to the AutgoGraph team. When filing the bug, set the verbosity to 10 (on Linux, `export AUTOGRAPH_VERBOSITY=10`) and attach the full output. Cause: converting <bound method Conv.call of <tensorflow.python.layers.convolutional.Conv2D object at 0x7fc0941bcf60>>: AssertionError: Bad argument number for Name: 3, expecting 4
W0518 07:35:24.516403 140469935716096 ag_logging.py:145] Entity <bound method Conv.call of <tensorflow.python.layers.convolutional.Conv2D object at 0x7fc0941bcf60>> could not be transformed and will be executed as-is. Please report this to the AutgoGraph team. When filing the bug, set the verbosity to 10 (on Linux, `export AUTOGRAPH_VERBOSITY=10`) and attach the full output. Cause: converting <bound method Conv.call of <tensorflow.python.layers.convolutional.Conv2D object at 0x7fc0941bcf60>>: AssertionError: Bad argument number for Name: 3, expecting 4
WARNING:tensorflow:Entity <bound method BatchNormalization.call of <tensorflow.python.layers.normalization.BatchNormalization object at 0x7fc100e1c908>> could not be transformed and will be executed as-is. Please report this to the AutgoGraph team. When filing the bug, set the verbosity to 10 (on Linux, `export AUTOGRAPH_VERBOSITY=10`) and attach the full output. Cause: converting <bound method BatchNormalization.call of <tensorflow.python.layers.normalization.BatchNormalization object at 0x7fc100e1c908>>: AssertionError: Bad argument number for Name: 3, expecting 4
W0518 07:35:24.542227 140469935716096 ag_logging.py:145] Entity <bound method BatchNormalization.call of <tensorflow.python.layers.normalization.BatchNormalization object at 0x7fc100e1c908>> could not be transformed and will be executed as-is. Please report this to the AutgoGraph team. When filing the bug, set the verbosity to 10 (on Linux, `export AUTOGRAPH_VERBOSITY=10`) and attach the full output. Cause: converting <bound method BatchNormalization.call of <tensorflow.python.layers.normalization.BatchNormalization object at 0x7fc100e1c908>>: AssertionError: Bad argument number for Name: 3, expecting 4
WARNING:tensorflow:Entity <bound method Conv.call of <tensorflow.python.layers.convolutional.Conv2D object at 0x7fc0941bcf60>> could not be transformed and will be executed as-is. Please report this to the AutgoGraph team. When filing the bug, set the verbosity to 10 (on Linux, `export AUTOGRAPH_VERBOSITY=10`) and attach the full output. Cause: converting <bound method Conv.call of <tensorflow.python.layers.convolutional.Conv2D object at 0x7fc0941bcf60>>: AssertionError: Bad argument number for Name: 3, expecting 4
W0518 07:35:24.602546 140469935716096 ag_logging.py:145] Entity <bound method Conv.call of <tensorflow.python.layers.convolutional.Conv2D object at 0x7fc0941bcf60>> could not be transformed and will be executed as-is. Please report this to the AutgoGraph team. When filing the bug, set the verbosity to 10 (on Linux, `export AUTOGRAPH_VERBOSITY=10`) and attach the full output. Cause: converting <bound method Conv.call of <tensorflow.python.layers.convolutional.Conv2D object at 0x7fc0941bcf60>>: AssertionError: Bad argument number for Name: 3, expecting 4
WARNING:tensorflow:Entity <bound method BatchNormalization.call of <tensorflow.python.layers.normalization.BatchNormalization object at 0x7fc100e1c908>> could not be transformed and will be executed as-is. Please report this to the AutgoGraph team. When filing the bug, set the verbosity to 10 (on Linux, `export AUTOGRAPH_VERBOSITY=10`) and attach the full output. Cause: converting <bound method BatchNormalization.call of <tensorflow.python.layers.normalization.BatchNormalization object at 0x7fc100e1c908>>: AssertionError: Bad argument number for Name: 3, expecting 4
W0518 07:35:24.627721 140469935716096 ag_logging.py:145] Entity <bound method BatchNormalization.call of <tensorflow.python.layers.normalization.BatchNormalization object at 0x7fc100e1c908>> could not be transformed and will be executed as-is. Please report this to the AutgoGraph team. When filing the bug, set the verbosity to 10 (on Linux, `export AUTOGRAPH_VERBOSITY=10`) and attach the full output. Cause: converting <bound method BatchNormalization.call of <tensorflow.python.layers.normalization.BatchNormalization object at 0x7fc100e1c908>>: AssertionError: Bad argument number for Name: 3, expecting 4
WARNING:tensorflow:Entity <bound method Conv.call of <tensorflow.python.layers.convolutional.Conv2D object at 0x7fc0185c0438>> could not be transformed and will be executed as-is. Please report this to the AutgoGraph team. When filing the bug, set the verbosity to 10 (on Linux, `export AUTOGRAPH_VERBOSITY=10`) and attach the full output. Cause: converting <bound method Conv.call of <tensorflow.python.layers.convolutional.Conv2D object at 0x7fc0185c0438>>: AssertionError: Bad argument number for Name: 3, expecting 4
W0518 07:35:24.689495 140469935716096 ag_logging.py:145] Entity <bound method Conv.call of <tensorflow.python.layers.convolutional.Conv2D object at 0x7fc0185c0438>> could not be transformed and will be executed as-is. Please report this to the AutgoGraph team. When filing the bug, set the verbosity to 10 (on Linux, `export AUTOGRAPH_VERBOSITY=10`) and attach the full output. Cause: converting <bound method Conv.call of <tensorflow.python.layers.convolutional.Conv2D object at 0x7fc0185c0438>>: AssertionError: Bad argument number for Name: 3, expecting 4
WARNING:tensorflow:Entity <bound method BatchNormalization.call of <tensorflow.python.layers.normalization.BatchNormalization object at 0x7fc0700190f0>> could not be transformed and will be executed as-is. Please report this to the AutgoGraph team. When filing the bug, set the verbosity to 10 (on Linux, `export AUTOGRAPH_VERBOSITY=10`) and attach the full output. Cause: converting <bound method BatchNormalization.call of <tensorflow.python.layers.normalization.BatchNormalization object at 0x7fc0700190f0>>: AssertionError: Bad argument number for Name: 3, expecting 4
W0518 07:35:24.714927 140469935716096 ag_logging.py:145] Entity <bound method BatchNormalization.call of <tensorflow.python.layers.normalization.BatchNormalization object at 0x7fc0700190f0>> could not be transformed and will be executed as-is. Please report this to the AutgoGraph team. When filing the bug, set the verbosity to 10 (on Linux, `export AUTOGRAPH_VERBOSITY=10`) and attach the full output. Cause: converting <bound method BatchNormalization.call of <tensorflow.python.layers.normalization.BatchNormalization object at 0x7fc0700190f0>>: AssertionError: Bad argument number for Name: 3, expecting 4
WARNING:tensorflow:Entity <bound method Conv.call of <tensorflow.python.layers.convolutional.Conv2D object at 0x7fc018561518>> could not be transformed and will be executed as-is. Please report this to the AutgoGraph team. When filing the bug, set the verbosity to 10 (on Linux, `export AUTOGRAPH_VERBOSITY=10`) and attach the full output. Cause: converting <bound method Conv.call of <tensorflow.python.layers.convolutional.Conv2D object at 0x7fc018561518>>: AssertionError: Bad argument number for Name: 3, expecting 4
W0518 07:35:24.776219 140469935716096 ag_logging.py:145] Entity <bound method Conv.call of <tensorflow.python.layers.convolutional.Conv2D object at 0x7fc018561518>> could not be transformed and will be executed as-is. Please report this to the AutgoGraph team. When filing the bug, set the verbosity to 10 (on Linux, `export AUTOGRAPH_VERBOSITY=10`) and attach the full output. Cause: converting <bound method Conv.call of <tensorflow.python.layers.convolutional.Conv2D object at 0x7fc018561518>>: AssertionError: Bad argument number for Name: 3, expecting 4
WARNING:tensorflow:Entity <bound method BatchNormalization.call of <tensorflow.python.layers.normalization.BatchNormalization object at 0x7fc0185c05f8>> could not be transformed and will be executed as-is. Please report this to the AutgoGraph team. When filing the bug, set the verbosity to 10 (on Linux, `export AUTOGRAPH_VERBOSITY=10`) and attach the full output. Cause: converting <bound method BatchNormalization.call of <tensorflow.python.layers.normalization.BatchNormalization object at 0x7fc0185c05f8>>: AssertionError: Bad argument number for Name: 3, expecting 4
W0518 07:35:24.801973 140469935716096 ag_logging.py:145] Entity <bound method BatchNormalization.call of <tensorflow.python.layers.normalization.BatchNormalization object at 0x7fc0185c05f8>> could not be transformed and will be executed as-is. Please report this to the AutgoGraph team. When filing the bug, set the verbosity to 10 (on Linux, `export AUTOGRAPH_VERBOSITY=10`) and attach the full output. Cause: converting <bound method BatchNormalization.call of <tensorflow.python.layers.normalization.BatchNormalization object at 0x7fc0185c05f8>>: AssertionError: Bad argument number for Name: 3, expecting 4
WARNING:tensorflow:Entity <bound method Conv.call of <tensorflow.python.layers.convolutional.Conv2D object at 0x7fc0940a56a0>> could not be transformed and will be executed as-is. Please report this to the AutgoGraph team. When filing the bug, set the verbosity to 10 (on Linux, `export AUTOGRAPH_VERBOSITY=10`) and attach the full output. Cause: converting <bound method Conv.call of <tensorflow.python.layers.convolutional.Conv2D object at 0x7fc0940a56a0>>: AssertionError: Bad argument number for Name: 3, expecting 4
W0518 07:35:24.861993 140469935716096 ag_logging.py:145] Entity <bound method Conv.call of <tensorflow.python.layers.convolutional.Conv2D object at 0x7fc0940a56a0>> could not be transformed and will be executed as-is. Please report this to the AutgoGraph team. When filing the bug, set the verbosity to 10 (on Linux, `export AUTOGRAPH_VERBOSITY=10`) and attach the full output. Cause: converting <bound method Conv.call of <tensorflow.python.layers.convolutional.Conv2D object at 0x7fc0940a56a0>>: AssertionError: Bad argument number for Name: 3, expecting 4
WARNING:tensorflow:Entity <bound method BatchNormalization.call of <tensorflow.python.layers.normalization.BatchNormalization object at 0x7fc040054fd0>> could not be transformed and will be executed as-is. Please report this to the AutgoGraph team. When filing the bug, set the verbosity to 10 (on Linux, `export AUTOGRAPH_VERBOSITY=10`) and attach the full output. Cause: converting <bound method BatchNormalization.call of <tensorflow.python.layers.normalization.BatchNormalization object at 0x7fc040054fd0>>: AssertionError: Bad argument number for Name: 3, expecting 4
W0518 07:35:24.887976 140469935716096 ag_logging.py:145] Entity <bound method BatchNormalization.call of <tensorflow.python.layers.normalization.BatchNormalization object at 0x7fc040054fd0>> could not be transformed and will be executed as-is. Please report this to the AutgoGraph team. When filing the bug, set the verbosity to 10 (on Linux, `export AUTOGRAPH_VERBOSITY=10`) and attach the full output. Cause: converting <bound method BatchNormalization.call of <tensorflow.python.layers.normalization.BatchNormalization object at 0x7fc040054fd0>>: AssertionError: Bad argument number for Name: 3, expecting 4
WARNING:tensorflow:Entity <bound method Conv.call of <tensorflow.python.layers.convolutional.Conv2D object at 0x7fc018606cf8>> could not be transformed and will be executed as-is. Please report this to the AutgoGraph team. When filing the bug, set the verbosity to 10 (on Linux, `export AUTOGRAPH_VERBOSITY=10`) and attach the full output. Cause: converting <bound method Conv.call of <tensorflow.python.layers.convolutional.Conv2D object at 0x7fc018606cf8>>: AssertionError: Bad argument number for Name: 3, expecting 4
W0518 07:35:24.949478 140469935716096 ag_logging.py:145] Entity <bound method Conv.call of <tensorflow.python.layers.convolutional.Conv2D object at 0x7fc018606cf8>> could not be transformed and will be executed as-is. Please report this to the AutgoGraph team. When filing the bug, set the verbosity to 10 (on Linux, `export AUTOGRAPH_VERBOSITY=10`) and attach the full output. Cause: converting <bound method Conv.call of <tensorflow.python.layers.convolutional.Conv2D object at 0x7fc018606cf8>>: AssertionError: Bad argument number for Name: 3, expecting 4
WARNING:tensorflow:Entity <bound method BatchNormalization.call of <tensorflow.python.layers.normalization.BatchNormalization object at 0x7fc040054fd0>> could not be transformed and will be executed as-is. Please report this to the AutgoGraph team. When filing the bug, set the verbosity to 10 (on Linux, `export AUTOGRAPH_VERBOSITY=10`) and attach the full output. Cause: converting <bound method BatchNormalization.call of <tensorflow.python.layers.normalization.BatchNormalization object at 0x7fc040054fd0>>: AssertionError: Bad argument number for Name: 3, expecting 4
W0518 07:35:24.975569 140469935716096 ag_logging.py:145] Entity <bound method BatchNormalization.call of <tensorflow.python.layers.normalization.BatchNormalization object at 0x7fc040054fd0>> could not be transformed and will be executed as-is. Please report this to the AutgoGraph team. When filing the bug, set the verbosity to 10 (on Linux, `export AUTOGRAPH_VERBOSITY=10`) and attach the full output. Cause: converting <bound method BatchNormalization.call of <tensorflow.python.layers.normalization.BatchNormalization object at 0x7fc040054fd0>>: AssertionError: Bad argument number for Name: 3, expecting 4
WARNING:tensorflow:Entity <bound method Conv.call of <tensorflow.python.layers.convolutional.Conv2D object at 0x7fc01859ac18>> could not be transformed and will be executed as-is. Please report this to the AutgoGraph team. When filing the bug, set the verbosity to 10 (on Linux, `export AUTOGRAPH_VERBOSITY=10`) and attach the full output. Cause: converting <bound method Conv.call of <tensorflow.python.layers.convolutional.Conv2D object at 0x7fc01859ac18>>: AssertionError: Bad argument number for Name: 3, expecting 4
W0518 07:35:25.036440 140469935716096 ag_logging.py:145] Entity <bound method Conv.call of <tensorflow.python.layers.convolutional.Conv2D object at 0x7fc01859ac18>> could not be transformed and will be executed as-is. Please report this to the AutgoGraph team. When filing the bug, set the verbosity to 10 (on Linux, `export AUTOGRAPH_VERBOSITY=10`) and attach the full output. Cause: converting <bound method Conv.call of <tensorflow.python.layers.convolutional.Conv2D object at 0x7fc01859ac18>>: AssertionError: Bad argument number for Name: 3, expecting 4
WARNING:tensorflow:Entity <bound method BatchNormalization.call of <tensorflow.python.layers.normalization.BatchNormalization object at 0x7fc040054fd0>> could not be transformed and will be executed as-is. Please report this to the AutgoGraph team. When filing the bug, set the verbosity to 10 (on Linux, `export AUTOGRAPH_VERBOSITY=10`) and attach the full output. Cause: converting <bound method BatchNormalization.call of <tensorflow.python.layers.normalization.BatchNormalization object at 0x7fc040054fd0>>: AssertionError: Bad argument number for Name: 3, expecting 4
W0518 07:35:25.062235 140469935716096 ag_logging.py:145] Entity <bound method BatchNormalization.call of <tensorflow.python.layers.normalization.BatchNormalization object at 0x7fc040054fd0>> could not be transformed and will be executed as-is. Please report this to the AutgoGraph team. When filing the bug, set the verbosity to 10 (on Linux, `export AUTOGRAPH_VERBOSITY=10`) and attach the full output. Cause: converting <bound method BatchNormalization.call of <tensorflow.python.layers.normalization.BatchNormalization object at 0x7fc040054fd0>>: AssertionError: Bad argument number for Name: 3, expecting 4
WARNING:tensorflow:Entity <bound method Conv.call of <tensorflow.python.layers.convolutional.Conv2D object at 0x7fc01859ac18>> could not be transformed and will be executed as-is. Please report this to the AutgoGraph team. When filing the bug, set the verbosity to 10 (on Linux, `export AUTOGRAPH_VERBOSITY=10`) and attach the full output. Cause: converting <bound method Conv.call of <tensorflow.python.layers.convolutional.Conv2D object at 0x7fc01859ac18>>: AssertionError: Bad argument number for Name: 3, expecting 4
W0518 07:35:25.194870 140469935716096 ag_logging.py:145] Entity <bound method Conv.call of <tensorflow.python.layers.convolutional.Conv2D object at 0x7fc01859ac18>> could not be transformed and will be executed as-is. Please report this to the AutgoGraph team. When filing the bug, set the verbosity to 10 (on Linux, `export AUTOGRAPH_VERBOSITY=10`) and attach the full output. Cause: converting <bound method Conv.call of <tensorflow.python.layers.convolutional.Conv2D object at 0x7fc01859ac18>>: AssertionError: Bad argument number for Name: 3, expecting 4
WARNING:tensorflow:Entity <bound method BatchNormalization.call of <tensorflow.python.layers.normalization.BatchNormalization object at 0x7fc040054fd0>> could not be transformed and will be executed as-is. Please report this to the AutgoGraph team. When filing the bug, set the verbosity to 10 (on Linux, `export AUTOGRAPH_VERBOSITY=10`) and attach the full output. Cause: converting <bound method BatchNormalization.call of <tensorflow.python.layers.normalization.BatchNormalization object at 0x7fc040054fd0>>: AssertionError: Bad argument number for Name: 3, expecting 4
W0518 07:35:25.223088 140469935716096 ag_logging.py:145] Entity <bound method BatchNormalization.call of <tensorflow.python.layers.normalization.BatchNormalization object at 0x7fc040054fd0>> could not be transformed and will be executed as-is. Please report this to the AutgoGraph team. When filing the bug, set the verbosity to 10 (on Linux, `export AUTOGRAPH_VERBOSITY=10`) and attach the full output. Cause: converting <bound method BatchNormalization.call of <tensorflow.python.layers.normalization.BatchNormalization object at 0x7fc040054fd0>>: AssertionError: Bad argument number for Name: 3, expecting 4
WARNING:tensorflow:Entity <bound method Conv.call of <tensorflow.python.layers.convolutional.Conv2D object at 0x7fc01859aeb8>> could not be transformed and will be executed as-is. Please report this to the AutgoGraph team. When filing the bug, set the verbosity to 10 (on Linux, `export AUTOGRAPH_VERBOSITY=10`) and attach the full output. Cause: converting <bound method Conv.call of <tensorflow.python.layers.convolutional.Conv2D object at 0x7fc01859aeb8>>: AssertionError: Bad argument number for Name: 3, expecting 4
W0518 07:35:25.284678 140469935716096 ag_logging.py:145] Entity <bound method Conv.call of <tensorflow.python.layers.convolutional.Conv2D object at 0x7fc01859aeb8>> could not be transformed and will be executed as-is. Please report this to the AutgoGraph team. When filing the bug, set the verbosity to 10 (on Linux, `export AUTOGRAPH_VERBOSITY=10`) and attach the full output. Cause: converting <bound method Conv.call of <tensorflow.python.layers.convolutional.Conv2D object at 0x7fc01859aeb8>>: AssertionError: Bad argument number for Name: 3, expecting 4
WARNING:tensorflow:Entity <bound method BatchNormalization.call of <tensorflow.python.layers.normalization.BatchNormalization object at 0x7fc040054fd0>> could not be transformed and will be executed as-is. Please report this to the AutgoGraph team. When filing the bug, set the verbosity to 10 (on Linux, `export AUTOGRAPH_VERBOSITY=10`) and attach the full output. Cause: converting <bound method BatchNormalization.call of <tensorflow.python.layers.normalization.BatchNormalization object at 0x7fc040054fd0>>: AssertionError: Bad argument number for Name: 3, expecting 4
W0518 07:35:25.310205 140469935716096 ag_logging.py:145] Entity <bound method BatchNormalization.call of <tensorflow.python.layers.normalization.BatchNormalization object at 0x7fc040054fd0>> could not be transformed and will be executed as-is. Please report this to the AutgoGraph team. When filing the bug, set the verbosity to 10 (on Linux, `export AUTOGRAPH_VERBOSITY=10`) and attach the full output. Cause: converting <bound method BatchNormalization.call of <tensorflow.python.layers.normalization.BatchNormalization object at 0x7fc040054fd0>>: AssertionError: Bad argument number for Name: 3, expecting 4
WARNING:tensorflow:Entity <bound method Conv.call of <tensorflow.python.layers.convolutional.Conv2D object at 0x7fc018575fd0>> could not be transformed and will be executed as-is. Please report this to the AutgoGraph team. When filing the bug, set the verbosity to 10 (on Linux, `export AUTOGRAPH_VERBOSITY=10`) and attach the full output. Cause: converting <bound method Conv.call of <tensorflow.python.layers.convolutional.Conv2D object at 0x7fc018575fd0>>: AssertionError: Bad argument number for Name: 3, expecting 4
W0518 07:35:25.374163 140469935716096 ag_logging.py:145] Entity <bound method Conv.call of <tensorflow.python.layers.convolutional.Conv2D object at 0x7fc018575fd0>> could not be transformed and will be executed as-is. Please report this to the AutgoGraph team. When filing the bug, set the verbosity to 10 (on Linux, `export AUTOGRAPH_VERBOSITY=10`) and attach the full output. Cause: converting <bound method Conv.call of <tensorflow.python.layers.convolutional.Conv2D object at 0x7fc018575fd0>>: AssertionError: Bad argument number for Name: 3, expecting 4
WARNING:tensorflow:Entity <bound method BatchNormalization.call of <tensorflow.python.layers.normalization.BatchNormalization object at 0x7fc0940a56a0>> could not be transformed and will be executed as-is. Please report this to the AutgoGraph team. When filing the bug, set the verbosity to 10 (on Linux, `export AUTOGRAPH_VERBOSITY=10`) and attach the full output. Cause: converting <bound method BatchNormalization.call of <tensorflow.python.layers.normalization.BatchNormalization object at 0x7fc0940a56a0>>: AssertionError: Bad argument number for Name: 3, expecting 4
W0518 07:35:25.400130 140469935716096 ag_logging.py:145] Entity <bound method BatchNormalization.call of <tensorflow.python.layers.normalization.BatchNormalization object at 0x7fc0940a56a0>> could not be transformed and will be executed as-is. Please report this to the AutgoGraph team. When filing the bug, set the verbosity to 10 (on Linux, `export AUTOGRAPH_VERBOSITY=10`) and attach the full output. Cause: converting <bound method BatchNormalization.call of <tensorflow.python.layers.normalization.BatchNormalization object at 0x7fc0940a56a0>>: AssertionError: Bad argument number for Name: 3, expecting 4
WARNING:tensorflow:Entity <bound method Conv.call of <tensorflow.python.layers.convolutional.Conv2D object at 0x7fc102571358>> could not be transformed and will be executed as-is. Please report this to the AutgoGraph team. When filing the bug, set the verbosity to 10 (on Linux, `export AUTOGRAPH_VERBOSITY=10`) and attach the full output. Cause: converting <bound method Conv.call of <tensorflow.python.layers.convolutional.Conv2D object at 0x7fc102571358>>: AssertionError: Bad argument number for Name: 3, expecting 4
W0518 07:35:25.462808 140469935716096 ag_logging.py:145] Entity <bound method Conv.call of <tensorflow.python.layers.convolutional.Conv2D object at 0x7fc102571358>> could not be transformed and will be executed as-is. Please report this to the AutgoGraph team. When filing the bug, set the verbosity to 10 (on Linux, `export AUTOGRAPH_VERBOSITY=10`) and attach the full output. Cause: converting <bound method Conv.call of <tensorflow.python.layers.convolutional.Conv2D object at 0x7fc102571358>>: AssertionError: Bad argument number for Name: 3, expecting 4
WARNING:tensorflow:Entity <bound method BatchNormalization.call of <tensorflow.python.layers.normalization.BatchNormalization object at 0x7fc1011128d0>> could not be transformed and will be executed as-is. Please report this to the AutgoGraph team. When filing the bug, set the verbosity to 10 (on Linux, `export AUTOGRAPH_VERBOSITY=10`) and attach the full output. Cause: converting <bound method BatchNormalization.call of <tensorflow.python.layers.normalization.BatchNormalization object at 0x7fc1011128d0>>: AssertionError: Bad argument number for Name: 3, expecting 4
W0518 07:35:25.488571 140469935716096 ag_logging.py:145] Entity <bound method BatchNormalization.call of <tensorflow.python.layers.normalization.BatchNormalization object at 0x7fc1011128d0>> could not be transformed and will be executed as-is. Please report this to the AutgoGraph team. When filing the bug, set the verbosity to 10 (on Linux, `export AUTOGRAPH_VERBOSITY=10`) and attach the full output. Cause: converting <bound method BatchNormalization.call of <tensorflow.python.layers.normalization.BatchNormalization object at 0x7fc1011128d0>>: AssertionError: Bad argument number for Name: 3, expecting 4
WARNING:tensorflow:Entity <bound method Conv.call of <tensorflow.python.layers.convolutional.Conv2D object at 0x7fc100e66048>> could not be transformed and will be executed as-is. Please report this to the AutgoGraph team. When filing the bug, set the verbosity to 10 (on Linux, `export AUTOGRAPH_VERBOSITY=10`) and attach the full output. Cause: converting <bound method Conv.call of <tensorflow.python.layers.convolutional.Conv2D object at 0x7fc100e66048>>: AssertionError: Bad argument number for Name: 3, expecting 4
W0518 07:35:25.547550 140469935716096 ag_logging.py:145] Entity <bound method Conv.call of <tensorflow.python.layers.convolutional.Conv2D object at 0x7fc100e66048>> could not be transformed and will be executed as-is. Please report this to the AutgoGraph team. When filing the bug, set the verbosity to 10 (on Linux, `export AUTOGRAPH_VERBOSITY=10`) and attach the full output. Cause: converting <bound method Conv.call of <tensorflow.python.layers.convolutional.Conv2D object at 0x7fc100e66048>>: AssertionError: Bad argument number for Name: 3, expecting 4
WARNING:tensorflow:Entity <bound method BatchNormalization.call of <tensorflow.python.layers.normalization.BatchNormalization object at 0x7fc1011128d0>> could not be transformed and will be executed as-is. Please report this to the AutgoGraph team. When filing the bug, set the verbosity to 10 (on Linux, `export AUTOGRAPH_VERBOSITY=10`) and attach the full output. Cause: converting <bound method BatchNormalization.call of <tensorflow.python.layers.normalization.BatchNormalization object at 0x7fc1011128d0>>: AssertionError: Bad argument number for Name: 3, expecting 4
W0518 07:35:25.573518 140469935716096 ag_logging.py:145] Entity <bound method BatchNormalization.call of <tensorflow.python.layers.normalization.BatchNormalization object at 0x7fc1011128d0>> could not be transformed and will be executed as-is. Please report this to the AutgoGraph team. When filing the bug, set the verbosity to 10 (on Linux, `export AUTOGRAPH_VERBOSITY=10`) and attach the full output. Cause: converting <bound method BatchNormalization.call of <tensorflow.python.layers.normalization.BatchNormalization object at 0x7fc1011128d0>>: AssertionError: Bad argument number for Name: 3, expecting 4
WARNING:tensorflow:Entity <bound method Conv.call of <tensorflow.python.layers.convolutional.Conv2D object at 0x7fc1024e6198>> could not be transformed and will be executed as-is. Please report this to the AutgoGraph team. When filing the bug, set the verbosity to 10 (on Linux, `export AUTOGRAPH_VERBOSITY=10`) and attach the full output. Cause: converting <bound method Conv.call of <tensorflow.python.layers.convolutional.Conv2D object at 0x7fc1024e6198>>: AssertionError: Bad argument number for Name: 3, expecting 4
W0518 07:35:25.634675 140469935716096 ag_logging.py:145] Entity <bound method Conv.call of <tensorflow.python.layers.convolutional.Conv2D object at 0x7fc1024e6198>> could not be transformed and will be executed as-is. Please report this to the AutgoGraph team. When filing the bug, set the verbosity to 10 (on Linux, `export AUTOGRAPH_VERBOSITY=10`) and attach the full output. Cause: converting <bound method Conv.call of <tensorflow.python.layers.convolutional.Conv2D object at 0x7fc1024e6198>>: AssertionError: Bad argument number for Name: 3, expecting 4
WARNING:tensorflow:Entity <bound method BatchNormalization.call of <tensorflow.python.layers.normalization.BatchNormalization object at 0x7fc1011128d0>> could not be transformed and will be executed as-is. Please report this to the AutgoGraph team. When filing the bug, set the verbosity to 10 (on Linux, `export AUTOGRAPH_VERBOSITY=10`) and attach the full output. Cause: converting <bound method BatchNormalization.call of <tensorflow.python.layers.normalization.BatchNormalization object at 0x7fc1011128d0>>: AssertionError: Bad argument number for Name: 3, expecting 4
W0518 07:35:25.660579 140469935716096 ag_logging.py:145] Entity <bound method BatchNormalization.call of <tensorflow.python.layers.normalization.BatchNormalization object at 0x7fc1011128d0>> could not be transformed and will be executed as-is. Please report this to the AutgoGraph team. When filing the bug, set the verbosity to 10 (on Linux, `export AUTOGRAPH_VERBOSITY=10`) and attach the full output. Cause: converting <bound method BatchNormalization.call of <tensorflow.python.layers.normalization.BatchNormalization object at 0x7fc1011128d0>>: AssertionError: Bad argument number for Name: 3, expecting 4
WARNING:tensorflow:Entity <bound method Conv.call of <tensorflow.python.layers.convolutional.Conv2D object at 0x7fc101fd1320>> could not be transformed and will be executed as-is. Please report this to the AutgoGraph team. When filing the bug, set the verbosity to 10 (on Linux, `export AUTOGRAPH_VERBOSITY=10`) and attach the full output. Cause: converting <bound method Conv.call of <tensorflow.python.layers.convolutional.Conv2D object at 0x7fc101fd1320>>: AssertionError: Bad argument number for Name: 3, expecting 4
W0518 07:35:25.721008 140469935716096 ag_logging.py:145] Entity <bound method Conv.call of <tensorflow.python.layers.convolutional.Conv2D object at 0x7fc101fd1320>> could not be transformed and will be executed as-is. Please report this to the AutgoGraph team. When filing the bug, set the verbosity to 10 (on Linux, `export AUTOGRAPH_VERBOSITY=10`) and attach the full output. Cause: converting <bound method Conv.call of <tensorflow.python.layers.convolutional.Conv2D object at 0x7fc101fd1320>>: AssertionError: Bad argument number for Name: 3, expecting 4
WARNING:tensorflow:Entity <bound method BatchNormalization.call of <tensorflow.python.layers.normalization.BatchNormalization object at 0x7fc1011128d0>> could not be transformed and will be executed as-is. Please report this to the AutgoGraph team. When filing the bug, set the verbosity to 10 (on Linux, `export AUTOGRAPH_VERBOSITY=10`) and attach the full output. Cause: converting <bound method BatchNormalization.call of <tensorflow.python.layers.normalization.BatchNormalization object at 0x7fc1011128d0>>: AssertionError: Bad argument number for Name: 3, expecting 4
W0518 07:35:25.746803 140469935716096 ag_logging.py:145] Entity <bound method BatchNormalization.call of <tensorflow.python.layers.normalization.BatchNormalization object at 0x7fc1011128d0>> could not be transformed and will be executed as-is. Please report this to the AutgoGraph team. When filing the bug, set the verbosity to 10 (on Linux, `export AUTOGRAPH_VERBOSITY=10`) and attach the full output. Cause: converting <bound method BatchNormalization.call of <tensorflow.python.layers.normalization.BatchNormalization object at 0x7fc1011128d0>>: AssertionError: Bad argument number for Name: 3, expecting 4
WARNING:tensorflow:Entity <bound method Dense.call of <tensorflow.python.layers.core.Dense object at 0x7fc0d8112e48>> could not be transformed and will be executed as-is. Please report this to the AutgoGraph team. When filing the bug, set the verbosity to 10 (on Linux, `export AUTOGRAPH_VERBOSITY=10`) and attach the full output. Cause: converting <bound method Dense.call of <tensorflow.python.layers.core.Dense object at 0x7fc0d8112e48>>: AssertionError: Bad argument number for Name: 3, expecting 4
W0518 07:35:25.838299 140469935716096 ag_logging.py:145] Entity <bound method Dense.call of <tensorflow.python.layers.core.Dense object at 0x7fc0d8112e48>> could not be transformed and will be executed as-is. Please report this to the AutgoGraph team. When filing the bug, set the verbosity to 10 (on Linux, `export AUTOGRAPH_VERBOSITY=10`) and attach the full output. Cause: converting <bound method Dense.call of <tensorflow.python.layers.core.Dense object at 0x7fc0d8112e48>>: AssertionError: Bad argument number for Name: 3, expecting 4
INFO:tensorflow:Done calling model_fn.
I0518 07:35:25.841974 140469935716096 estimator.py:1147] Done calling model_fn.
WARNING:tensorflow:From /home/jon/anaconda3/envs/tf1.14-gpu/lib/python3.6/site-packages/tensorflow/python/saved_model/signature_def_utils_impl.py:201: build_tensor_info (from tensorflow.python.saved_model.utils_impl) is deprecated and will be removed in a future version.
Instructions for updating:
This function will only be available through the v1 compatibility library as tf.compat.v1.saved_model.utils.build_tensor_info or tf.compat.v1.saved_model.build_tensor_info.
W0518 07:35:25.842138 140469935716096 deprecation.py:323] From /home/jon/anaconda3/envs/tf1.14-gpu/lib/python3.6/site-packages/tensorflow/python/saved_model/signature_def_utils_impl.py:201: build_tensor_info (from tensorflow.python.saved_model.utils_impl) is deprecated and will be removed in a future version.
Instructions for updating:
This function will only be available through the v1 compatibility library as tf.compat.v1.saved_model.utils.build_tensor_info or tf.compat.v1.saved_model.build_tensor_info.
INFO:tensorflow:Signatures INCLUDED in export for Classify: None
I0518 07:35:25.842457 140469935716096 export_utils.py:170] Signatures INCLUDED in export for Classify: None
INFO:tensorflow:Signatures INCLUDED in export for Regress: None
I0518 07:35:25.842530 140469935716096 export_utils.py:170] Signatures INCLUDED in export for Regress: None
INFO:tensorflow:Signatures INCLUDED in export for Predict: ['predict', 'serving_default']
I0518 07:35:25.842617 140469935716096 export_utils.py:170] Signatures INCLUDED in export for Predict: ['predict', 'serving_default']
INFO:tensorflow:Signatures INCLUDED in export for Train: None
I0518 07:35:25.842672 140469935716096 export_utils.py:170] Signatures INCLUDED in export for Train: None
INFO:tensorflow:Signatures INCLUDED in export for Eval: None
I0518 07:35:25.842724 140469935716096 export_utils.py:170] Signatures INCLUDED in export for Eval: None
2020-05-18 07:35:25.843387: I tensorflow/core/common_runtime/gpu/gpu_device.cc:1640] Found device 0 with properties: 
name: GeForce GTX 1080 Ti major: 6 minor: 1 memoryClockRate(GHz): 1.6705
pciBusID: 0000:02:00.0
2020-05-18 07:35:25.844287: I tensorflow/core/common_runtime/gpu/gpu_device.cc:1640] Found device 1 with properties: 
name: GeForce GTX 1080 Ti major: 6 minor: 1 memoryClockRate(GHz): 1.6705
pciBusID: 0000:03:00.0
2020-05-18 07:35:25.844338: I tensorflow/stream_executor/platform/default/dso_loader.cc:42] Successfully opened dynamic library libcudart.so.10.0
2020-05-18 07:35:25.844351: I tensorflow/stream_executor/platform/default/dso_loader.cc:42] Successfully opened dynamic library libcublas.so.10.0
2020-05-18 07:35:25.844360: I tensorflow/stream_executor/platform/default/dso_loader.cc:42] Successfully opened dynamic library libcufft.so.10.0
2020-05-18 07:35:25.844369: I tensorflow/stream_executor/platform/default/dso_loader.cc:42] Successfully opened dynamic library libcurand.so.10.0
2020-05-18 07:35:25.844378: I tensorflow/stream_executor/platform/default/dso_loader.cc:42] Successfully opened dynamic library libcusolver.so.10.0
2020-05-18 07:35:25.844387: I tensorflow/stream_executor/platform/default/dso_loader.cc:42] Successfully opened dynamic library libcusparse.so.10.0
2020-05-18 07:35:25.844396: I tensorflow/stream_executor/platform/default/dso_loader.cc:42] Successfully opened dynamic library libcudnn.so.7
2020-05-18 07:35:25.846586: I tensorflow/core/common_runtime/gpu/gpu_device.cc:1763] Adding visible gpu devices: 0, 1
2020-05-18 07:35:25.846656: I tensorflow/core/common_runtime/gpu/gpu_device.cc:1181] Device interconnect StreamExecutor with strength 1 edge matrix:
2020-05-18 07:35:25.846664: I tensorflow/core/common_runtime/gpu/gpu_device.cc:1187]      0 1 
2020-05-18 07:35:25.846670: I tensorflow/core/common_runtime/gpu/gpu_device.cc:1200] 0:   N Y 
2020-05-18 07:35:25.846674: I tensorflow/core/common_runtime/gpu/gpu_device.cc:1200] 1:   Y N 
2020-05-18 07:35:25.848149: I tensorflow/core/common_runtime/gpu/gpu_device.cc:1326] Created TensorFlow device (/job:localhost/replica:0/task:0/device:GPU:0 with 10083 MB memory) -> physical GPU (device: 0, name: GeForce GTX 1080 Ti, pci bus id: 0000:02:00.0, compute capability: 6.1)
2020-05-18 07:35:25.849096: I tensorflow/core/common_runtime/gpu/gpu_device.cc:1326] Created TensorFlow device (/job:localhost/replica:0/task:0/device:GPU:1 with 10479 MB memory) -> physical GPU (device: 1, name: GeForce GTX 1080 Ti, pci bus id: 0000:03:00.0, compute capability: 6.1)
INFO:tensorflow:Restoring parameters from ./resnet_21/model.ckpt-4802119
I0518 07:35:25.953685 140469935716096 saver.py:1280] Restoring parameters from ./resnet_21/model.ckpt-4802119
INFO:tensorflow:Assets added to graph.
I0518 07:35:26.155634 140469935716096 builder_impl.py:661] Assets added to graph.
INFO:tensorflow:No assets to write.
I0518 07:35:26.155782 140469935716096 builder_impl.py:456] No assets to write.
INFO:tensorflow:SavedModel written to: ./resnet_21/export_model/temp-b'1589801723'/saved_model.pb
I0518 07:35:26.386734 140469935716096 builder_impl.py:421] SavedModel written to: ./resnet_21/export_model/temp-b'1589801723'/saved_model.pb
